2017-12-24 21:12:42,959 - dbBaseHelper - 7800 - ERROR - write - write sql:
        insert into user (userName,phone,sex,Gmt) values (%(user_name)s,%(user_phone)s,%(user_sex)s,now())
         args:{'phone': u'1xxxxxx', 'user_name': u'jes', 'sex': 'male'} Exception:Traceback (most recent call last):
  File "C:\python27\lib\site-packages\src-0.0.1-py2.7.egg\src\main\master\util\dbUtil\dbBaseHelper.py", line 56, in write
    db.write(sql,args,is_execute_many)
  File "C:\python27\lib\site-packages\src-0.0.1-py2.7.egg\src\main\master\util\dbUtil\dbBaseUtil.py", line 54, in write
    ret = c.execute(sql, args)
  File "c:\users\jessica\appdata\local\temp\easy_install-qvdkaj\MySQL_python-1.2.5-py2.7-win32.egg.tmp\MySQLdb\cursors.py", line 185, in execute
    for key, item in args.iteritems())
KeyError: 'user_phone'

2017-12-24 21:13:48,803 - dbBaseHelper - 7128 - ERROR - write - write sql:
        insert into user (userName,phone,sex,Gmt) values (%(user_name)s,%(user_phone)s,%(user_sex)s,now())
         args:{'user_phone': u'1xxxxxx', 'user_name': u'jes', 'sex': 'male'} Exception:Traceback (most recent call last):
  File "C:\python27\lib\site-packages\src-0.0.1-py2.7.egg\src\main\master\util\dbUtil\dbBaseHelper.py", line 56, in write
    db.write(sql,args,is_execute_many)
  File "C:\python27\lib\site-packages\src-0.0.1-py2.7.egg\src\main\master\util\dbUtil\dbBaseUtil.py", line 54, in write
    ret = c.execute(sql, args)
  File "c:\users\jessica\appdata\local\temp\easy_install-qvdkaj\MySQL_python-1.2.5-py2.7-win32.egg.tmp\MySQLdb\cursors.py", line 185, in execute
    for key, item in args.iteritems())
KeyError: 'user_sex'

2017-12-31 17:26:18,226 - dbBaseHelper - 9128 - ERROR - write - func [deleteUser] exec sql Not provided
2017-12-31 17:32:52,457 - dbBaseHelper - 9128 - ERROR - write - func [deleteUser] exec sql Not provided
2017-12-31 17:35:51,237 - dbBaseHelper - 6348 - ERROR - write - func [deleteUser] exec sql Not provided
2017-12-31 17:36:49,539 - dbBaseHelper - 6348 - ERROR - write - func [deleteUser] exec sql Not provided
2017-12-31 17:40:41,964 - dbBaseHelper - 8764 - ERROR - write - func [deleteUser] exec sql Not provided
2017-12-31 17:44:26,028 - dbBaseHelper - 8328 - ERROR - write - func [deleteUser] exec sql Not provided
2017-12-31 17:49:02,953 - dbBaseHelper - 8328 - ERROR - read - func [getUserInfo] exec sql Not provided
2017-12-31 17:51:43,868 - dbBaseHelper - 9116 - ERROR - read - select sql:
        select * from user where userName= %(user_name)s
         args:None Exception:Traceback (most recent call last):
  File "C:\python27\lib\site-packages\src-0.0.1-py2.7.egg\src\main\master\util\dbUtil\dbBaseHelper.py", line 38, in read
    ret = db.read(sql,args)
  File "C:\python27\lib\site-packages\src-0.0.1-py2.7.egg\src\main\master\util\dbUtil\dbBaseUtil.py", line 39, in read
    c.execute(sql, args)
  File "c:\users\jessica\appdata\local\temp\easy_install-qvdkaj\MySQL_python-1.2.5-py2.7-win32.egg.tmp\MySQLdb\cursors.py", line 205, in execute
    self.errorhandler(self, exc, value)
  File "c:\users\jessica\appdata\local\temp\easy_install-qvdkaj\MySQL_python-1.2.5-py2.7-win32.egg.tmp\MySQLdb\connections.py", line 36, in defaulterrorhandler
    raise errorclass, errorvalue
ProgrammingError: (1064, "You have an error in your SQL syntax; check the manual that corresponds to your MySQL server version for the right syntax to use near '%(user_name)s' at line 1")

2017-12-31 17:52:05,825 - dbBaseHelper - 9116 - ERROR - write - write sql:
        delete from user where userName= %(user_name)s
         args:None Exception:Traceback (most recent call last):
  File "C:\python27\lib\site-packages\src-0.0.1-py2.7.egg\src\main\master\util\dbUtil\dbBaseHelper.py", line 72, in write
    db.write(sql,args,is_execute_many)
  File "C:\python27\lib\site-packages\src-0.0.1-py2.7.egg\src\main\master\util\dbUtil\dbBaseUtil.py", line 54, in write
    ret = c.execute(sql, args)
  File "c:\users\jessica\appdata\local\temp\easy_install-qvdkaj\MySQL_python-1.2.5-py2.7-win32.egg.tmp\MySQLdb\cursors.py", line 205, in execute
    self.errorhandler(self, exc, value)
  File "c:\users\jessica\appdata\local\temp\easy_install-qvdkaj\MySQL_python-1.2.5-py2.7-win32.egg.tmp\MySQLdb\connections.py", line 36, in defaulterrorhandler
    raise errorclass, errorvalue
ProgrammingError: (1064, "You have an error in your SQL syntax; check the manual that corresponds to your MySQL server version for the right syntax to use near '%(user_name)s' at line 1")

2017-12-31 17:56:22,082 - dbBaseHelper - 5040 - INFO - write - 
        delete from user where userName= %(user_name)s
        
2017-12-31 17:56:22,082 - dbBaseHelper - 5040 - ERROR - write - write sql:
        delete from user where userName= %(user_name)s
         args:None Exception:Traceback (most recent call last):
  File "C:\python27\lib\site-packages\src-0.0.1-py2.7.egg\src\main\master\util\dbUtil\dbBaseHelper.py", line 73, in write
    db.write(sql,args,is_execute_many)
  File "C:\python27\lib\site-packages\src-0.0.1-py2.7.egg\src\main\master\util\dbUtil\dbBaseUtil.py", line 54, in write
    ret = c.execute(sql, args)
  File "c:\users\jessica\appdata\local\temp\easy_install-qvdkaj\MySQL_python-1.2.5-py2.7-win32.egg.tmp\MySQLdb\cursors.py", line 205, in execute
    self.errorhandler(self, exc, value)
  File "c:\users\jessica\appdata\local\temp\easy_install-qvdkaj\MySQL_python-1.2.5-py2.7-win32.egg.tmp\MySQLdb\connections.py", line 36, in defaulterrorhandler
    raise errorclass, errorvalue
ProgrammingError: (1064, "You have an error in your SQL syntax; check the manual that corresponds to your MySQL server version for the right syntax to use near '%(user_name)s' at line 1")

2017-12-31 17:57:03,344 - dbBaseHelper - 5040 - ERROR - read - select sql:
        select * from user where userName= %(user_name)s
         args:None Exception:Traceback (most recent call last):
  File "C:\python27\lib\site-packages\src-0.0.1-py2.7.egg\src\main\master\util\dbUtil\dbBaseHelper.py", line 38, in read
    ret = db.read(sql,args)
  File "C:\python27\lib\site-packages\src-0.0.1-py2.7.egg\src\main\master\util\dbUtil\dbBaseUtil.py", line 39, in read
    c.execute(sql, args)
  File "c:\users\jessica\appdata\local\temp\easy_install-qvdkaj\MySQL_python-1.2.5-py2.7-win32.egg.tmp\MySQLdb\cursors.py", line 205, in execute
    self.errorhandler(self, exc, value)
  File "c:\users\jessica\appdata\local\temp\easy_install-qvdkaj\MySQL_python-1.2.5-py2.7-win32.egg.tmp\MySQLdb\connections.py", line 36, in defaulterrorhandler
    raise errorclass, errorvalue
ProgrammingError: (1064, "You have an error in your SQL syntax; check the manual that corresponds to your MySQL server version for the right syntax to use near '%(user_name)s' at line 1")

2017-12-31 18:41:44,315 - dbBaseHelper - 2480 - ERROR - write - write sql:
        insert into user (userName,phone,sex,Gmt) values (%(user_name)s,%(user_phone)s,%(user_sex)s,now())
         args:{'createuserid': u'4', 'version': u'v0.1.0', 'name': u'SCP'} Exception:Traceback (most recent call last):
  File "C:\python27\lib\site-packages\src-0.0.1-py2.7.egg\src\main\master\util\dbUtil\dbBaseHelper.py", line 72, in write
    db.write(sql,self.args,self.is_execute_many)
  File "C:\python27\lib\site-packages\src-0.0.1-py2.7.egg\src\main\master\util\dbUtil\dbBaseUtil.py", line 54, in write
    ret = c.execute(sql, args)
  File "c:\users\jessica\appdata\local\temp\easy_install-qvdkaj\MySQL_python-1.2.5-py2.7-win32.egg.tmp\MySQLdb\cursors.py", line 185, in execute
    for key, item in args.iteritems())
KeyError: 'user_name'

2017-12-31 18:50:59,000 - dbBaseHelper - 6340 - ERROR - write - func [addProject] exec sql Not provided
2017-12-31 18:53:58,891 - dbBaseHelper - 6340 - ERROR - write - func [addProject] exec sql Not provided
2018-01-01 18:25:59,391 - dbBaseHelper - 8836 - ERROR - read - select sql:
        select * from project where name = %(name)s
         args:{'name': {'name': u'SCP'}} Exception:Traceback (most recent call last):
  File "C:\python27\lib\site-packages\src-0.0.1-py2.7.egg\src\main\master\util\dbUtil\dbBaseHelper.py", line 33, in read
    ret = db.read(self.sql,self.args)
  File "C:\python27\lib\site-packages\src-0.0.1-py2.7.egg\src\main\master\util\dbUtil\dbBaseUtil.py", line 39, in read
    c.execute(sql, args)
  File "c:\users\jessica\appdata\local\temp\easy_install-qvdkaj\MySQL_python-1.2.5-py2.7-win32.egg.tmp\MySQLdb\cursors.py", line 205, in execute
    self.errorhandler(self, exc, value)
  File "c:\users\jessica\appdata\local\temp\easy_install-qvdkaj\MySQL_python-1.2.5-py2.7-win32.egg.tmp\MySQLdb\connections.py", line 36, in defaulterrorhandler
    raise errorclass, errorvalue
ProgrammingError: (1064, 'You have an error in your SQL syntax; check the manual that corresponds to your MySQL server version for the right syntax to use near \'\'name\': "\'SCP\'"}\' at line 1')

2018-01-01 18:30:58,585 - dbBaseHelper - 8836 - ERROR - read - select sql:
        select * from project where name = %(name)s
         args:{'name': {'name': u'SCP'}} Exception:Traceback (most recent call last):
  File "C:\python27\lib\site-packages\src-0.0.1-py2.7.egg\src\main\master\util\dbUtil\dbBaseHelper.py", line 33, in read
    ret = db.read(self.sql,self.args)
  File "C:\python27\lib\site-packages\src-0.0.1-py2.7.egg\src\main\master\util\dbUtil\dbBaseUtil.py", line 39, in read
    c.execute(sql, args)
  File "c:\users\jessica\appdata\local\temp\easy_install-qvdkaj\MySQL_python-1.2.5-py2.7-win32.egg.tmp\MySQLdb\cursors.py", line 205, in execute
    self.errorhandler(self, exc, value)
  File "c:\users\jessica\appdata\local\temp\easy_install-qvdkaj\MySQL_python-1.2.5-py2.7-win32.egg.tmp\MySQLdb\connections.py", line 36, in defaulterrorhandler
    raise errorclass, errorvalue
ProgrammingError: (1064, 'You have an error in your SQL syntax; check the manual that corresponds to your MySQL server version for the right syntax to use near \'\'name\': "\'SCP\'"}\' at line 1')

2018-01-22 14:31:07,931 - dbBaseHelper - 7452 - ERROR - write - write sql:
        insert into user (username,passwd,remarks,gmt_create) values (%(userName)s,%(userPasswd)s,%(remarks)s,now())
         args:{u'username': u'jessica', u'passwd': u'123456', 'remarks': None} Exception:Traceback (most recent call last):
  File "C:\Python27\lib\site-packages\src-0.0.1-py2.7.egg\src\main\master\util\dbUtil\dbBaseHelper.py", line 58, in write
    db.write(self.sql,self.args,self.is_execute_many)
  File "C:\Python27\lib\site-packages\src-0.0.1-py2.7.egg\src\main\master\util\dbUtil\dbBaseUtil.py", line 54, in write
    ret = c.execute(sql, args)
  File "C:\Python27\lib\site-packages\MySQLdb\cursors.py", line 185, in execute
    for key, item in args.iteritems())
KeyError: 'userName'

2018-01-22 14:31:59,535 - dbBaseHelper - 7452 - ERROR - write - write sql:
        insert into user (username,passwd,remarks,gmt_create) values (%(userName)s,%(userPasswd)s,%(remarks)s,now())
         args:{u'userName': u'jessica', u'passwd': u'123456', 'remarks': None} Exception:Traceback (most recent call last):
  File "C:\Python27\lib\site-packages\src-0.0.1-py2.7.egg\src\main\master\util\dbUtil\dbBaseHelper.py", line 58, in write
    db.write(self.sql,self.args,self.is_execute_many)
  File "C:\Python27\lib\site-packages\src-0.0.1-py2.7.egg\src\main\master\util\dbUtil\dbBaseUtil.py", line 54, in write
    ret = c.execute(sql, args)
  File "C:\Python27\lib\site-packages\MySQLdb\cursors.py", line 185, in execute
    for key, item in args.iteritems())
KeyError: 'userPasswd'

2018-01-23 00:40:04,134 - dbBaseHelper - 1716 - ERROR - write - write sql:
        insert into project (name,create_username,create_userid,version,remarks,gmt_create) values (%(name)s,%(userName)s,%(userId)s,%(version)s,%(remarks)s,now())
         args:{'remarks': None, u'headers': {u'Content-type': u'application/json'}, 'version': None, u'data': {u'userName': u'jessica', u'remarks': u'\u5f53\u524d\u7248\u672c\u4e3av0.1.0\uff0c\u8be5\u9879\u76ee\u65b0\u589e\u62fc\u56e2\u5c0f\u7a0b\u5e8f', u'version': u'v0.1.0', u'userId': 1, u'name': u'SchoolpalShow'}, u'crossDomain': True} Exception:Traceback (most recent call last):
  File "C:\python27\lib\site-packages\src-0.0.1-py2.7.egg\src\main\master\util\dbUtil\dbBaseHelper.py", line 58, in write
    db.write(self.sql,self.args,self.is_execute_many)
  File "C:\python27\lib\site-packages\src-0.0.1-py2.7.egg\src\main\master\util\dbUtil\dbBaseUtil.py", line 54, in write
    ret = c.execute(sql, args)
  File "c:\users\jessica\appdata\local\temp\easy_install-qvdkaj\MySQL_python-1.2.5-py2.7-win32.egg.tmp\MySQLdb\cursors.py", line 185, in execute
    for key, item in args.iteritems())
KeyError: 'name'

2018-01-23 00:45:37,315 - dbBaseHelper - 4796 - ERROR - write - write sql:
        insert into project (name,create_username,create_userid,version,remarks,gmt_create) values (%(name)s,%(userName)s,%(userId)s,%(version)s,%(remarks)s,now())
         args:{'remarks': None, u'headers': {u'Content-type': u'application/json'}, 'version': None, u'data': {u'userName': u'jessica', u'remarks': u'\u5f53\u524d\u7248\u672c\u4e3av0.1.0\uff0c\u8be5\u9879\u76ee\u65b0\u589e\u62fc\u56e2\u5c0f\u7a0b\u5e8f', u'version': u'v0.1.0', u'userId': 1, u'name': u'SchoolpalShow'}, u'crossDomain': True} Exception:Traceback (most recent call last):
  File "C:\python27\lib\site-packages\src-0.0.1-py2.7.egg\src\main\master\util\dbUtil\dbBaseHelper.py", line 58, in write
    db.write(self.sql,self.args,self.is_execute_many)
  File "C:\python27\lib\site-packages\src-0.0.1-py2.7.egg\src\main\master\util\dbUtil\dbBaseUtil.py", line 54, in write
    ret = c.execute(sql, args)
  File "c:\users\jessica\appdata\local\temp\easy_install-qvdkaj\MySQL_python-1.2.5-py2.7-win32.egg.tmp\MySQLdb\cursors.py", line 185, in execute
    for key, item in args.iteritems())
KeyError: 'name'

2018-01-23 00:48:12,716 - dbBaseHelper - 4796 - ERROR - write - write sql:
        insert into project (name,create_username,create_userid,version,remarks,gmt_create) values (%(name)s,%(userName)s,%(userId)s,%(version)s,%(remarks)s,now())
         args:{'remarks': None, u'headers': {u'Content-type': u'application/json'}, 'version': None, u'params': {u'userName': u'jessica', u'remarks': u'\u5f53\u524d\u7248\u672c\u4e3av0.1.0\uff0c\u8be5\u9879\u76ee\u65b0\u589e\u62fc\u56e2\u5c0f\u7a0b\u5e8f', u'version': u'v0.1.0', u'userId': 1, u'name': u'SchoolpalShow'}, u'crossDomain': True} Exception:Traceback (most recent call last):
  File "C:\python27\lib\site-packages\src-0.0.1-py2.7.egg\src\main\master\util\dbUtil\dbBaseHelper.py", line 58, in write
    db.write(self.sql,self.args,self.is_execute_many)
  File "C:\python27\lib\site-packages\src-0.0.1-py2.7.egg\src\main\master\util\dbUtil\dbBaseUtil.py", line 54, in write
    ret = c.execute(sql, args)
  File "c:\users\jessica\appdata\local\temp\easy_install-qvdkaj\MySQL_python-1.2.5-py2.7-win32.egg.tmp\MySQLdb\cursors.py", line 185, in execute
    for key, item in args.iteritems())
KeyError: 'name'

2018-01-23 01:10:49,286 - dbBaseHelper - 6268 - ERROR - write - write sql:
        insert into project (name,create_username,create_userid,version,remarks,gmt_create) values (%(name)s,%(userName)s,%(userId)s,%(version)s,%(remarks)s,now())
         args:{u'userName': u'jessica', u'remarks': u'\u5f53\u524d\u7248\u672c\u4e3av0.1.0\uff0c\u8be5\u9879\u76ee\u65b0\u589e\u62fc\u56e2\u5c0f\u7a0b\u5e8f', u'version': u'v0.1.0', u'userId': 1, u'name': u'SchoolpalShow'} Exception:Traceback (most recent call last):
  File "C:\python27\lib\site-packages\src-0.0.1-py2.7.egg\src\main\master\util\dbUtil\dbBaseHelper.py", line 58, in write
    db.write(self.sql,self.args,self.is_execute_many)
  File "C:\python27\lib\site-packages\src-0.0.1-py2.7.egg\src\main\master\util\dbUtil\dbBaseUtil.py", line 54, in write
    ret = c.execute(sql, args)
  File "c:\users\jessica\appdata\local\temp\easy_install-qvdkaj\MySQL_python-1.2.5-py2.7-win32.egg.tmp\MySQLdb\cursors.py", line 205, in execute
    self.errorhandler(self, exc, value)
  File "c:\users\jessica\appdata\local\temp\easy_install-qvdkaj\MySQL_python-1.2.5-py2.7-win32.egg.tmp\MySQLdb\connections.py", line 36, in defaulterrorhandler
    raise errorclass, errorvalue
IntegrityError: (1062, "Duplicate entry 'SchoolpalShow' for key 'name'")

2018-01-23 18:44:40,348 - dbBaseHelper - 1372 - ERROR - write - write sql:
        insert into project (name,create_username,create_userid,version,remarks,gmt_create) values (%(name)s,%(userName)s,%(userId)s,%(version)s,%(remarks)s,now())
         args:{u'userName': u'jessica', u'remarks': u'\u5f53\u524d\u7248\u672c\u4e3av0.1.0\uff0c\u8be5\u9879\u76ee\u65b0\u589e\u62fc\u56e2\u5c0f\u7a0b\u5e8f', u'version': u'v0.1.0', u'userId': 0, u'name': u'SchoolpalShow'} Exception:Traceback (most recent call last):
  File "C:\Python27\lib\site-packages\src-0.0.1-py2.7.egg\src\main\master\util\dbUtil\dbBaseHelper.py", line 58, in write
    db.write(self.sql,self.args,self.is_execute_many)
  File "C:\Python27\lib\site-packages\src-0.0.1-py2.7.egg\src\main\master\util\dbUtil\dbBaseUtil.py", line 54, in write
    ret = c.execute(sql, args)
  File "C:\Python27\lib\site-packages\MySQLdb\cursors.py", line 205, in execute
    self.errorhandler(self, exc, value)
  File "C:\Python27\lib\site-packages\MySQLdb\connections.py", line 36, in defaulterrorhandler
    raise errorclass, errorvalue
IntegrityError: (1062, "Duplicate entry 'SchoolpalShow' for key 'name'")

2018-01-23 19:03:17,221 - dbBaseHelper - 8492 - ERROR - write - write sql:
        insert into project (name,create_username,create_userid,version,remarks,gmt_create) values (%(name)s,%(userName)s,%(userId)s,%(version)s,%(remarks)s,now())
         args:{u'userName': u'', u'remarks': u'', u'version': u'', u'userId': 0, u'name': u''} Exception:Traceback (most recent call last):
  File "C:\Python27\lib\site-packages\src-0.0.1-py2.7.egg\src\main\master\util\dbUtil\dbBaseHelper.py", line 58, in write
    db.write(self.sql,self.args,self.is_execute_many)
  File "C:\Python27\lib\site-packages\src-0.0.1-py2.7.egg\src\main\master\util\dbUtil\dbBaseUtil.py", line 54, in write
    ret = c.execute(sql, args)
  File "C:\Python27\lib\site-packages\MySQLdb\cursors.py", line 205, in execute
    self.errorhandler(self, exc, value)
  File "C:\Python27\lib\site-packages\MySQLdb\connections.py", line 36, in defaulterrorhandler
    raise errorclass, errorvalue
IntegrityError: (1062, "Duplicate entry '' for key 'name'")

2018-01-23 19:04:01,289 - dbBaseHelper - 8768 - ERROR - write - write sql:
        insert into project (name,create_username,create_userid,version,remarks,gmt_create) values (%(name)s,%(userName)s,%(userId)s,%(version)s,%(remarks)s,now())
         args:{u'userName': u'', u'remarks': u'', u'version': u'', u'userId': 0, u'name': u''} Exception:Traceback (most recent call last):
  File "C:\Python27\lib\site-packages\src-0.0.1-py2.7.egg\src\main\master\util\dbUtil\dbBaseHelper.py", line 58, in write
    db.write(self.sql,self.args,self.is_execute_many)
  File "C:\Python27\lib\site-packages\src-0.0.1-py2.7.egg\src\main\master\util\dbUtil\dbBaseUtil.py", line 54, in write
    ret = c.execute(sql, args)
  File "C:\Python27\lib\site-packages\MySQLdb\cursors.py", line 205, in execute
    self.errorhandler(self, exc, value)
  File "C:\Python27\lib\site-packages\MySQLdb\connections.py", line 36, in defaulterrorhandler
    raise errorclass, errorvalue
IntegrityError: (1062, "Duplicate entry '' for key 'name'")

2018-01-23 19:04:12,579 - dbBaseHelper - 6668 - ERROR - write - write sql:
        insert into project (name,create_username,create_userid,version,remarks,gmt_create) values (%(name)s,%(userName)s,%(userId)s,%(version)s,%(remarks)s,now())
         args:{u'userName': u'', u'remarks': u'', u'version': u'', u'userId': 0, u'name': u''} Exception:Traceback (most recent call last):
  File "C:\Python27\lib\site-packages\src-0.0.1-py2.7.egg\src\main\master\util\dbUtil\dbBaseHelper.py", line 58, in write
    db.write(self.sql,self.args,self.is_execute_many)
  File "C:\Python27\lib\site-packages\src-0.0.1-py2.7.egg\src\main\master\util\dbUtil\dbBaseUtil.py", line 54, in write
    ret = c.execute(sql, args)
  File "C:\Python27\lib\site-packages\MySQLdb\cursors.py", line 205, in execute
    self.errorhandler(self, exc, value)
  File "C:\Python27\lib\site-packages\MySQLdb\connections.py", line 36, in defaulterrorhandler
    raise errorclass, errorvalue
IntegrityError: (1062, "Duplicate entry '' for key 'name'")

2018-01-23 19:09:18,542 - dbBaseHelper - 8492 - ERROR - write - write sql:
        insert into project (name,create_username,create_userid,version,remarks,gmt_create) values (%(name)s,%(userName)s,%(userId)s,%(version)s,%(remarks)s,now())
         args:{u'userName': u'', u'remarks': u'', u'version': u'', u'userId': 0, u'name': u''} Exception:Traceback (most recent call last):
  File "C:\Python27\lib\site-packages\src-0.0.1-py2.7.egg\src\main\master\util\dbUtil\dbBaseHelper.py", line 58, in write
    db.write(self.sql,self.args,self.is_execute_many)
  File "C:\Python27\lib\site-packages\src-0.0.1-py2.7.egg\src\main\master\util\dbUtil\dbBaseUtil.py", line 54, in write
    ret = c.execute(sql, args)
  File "C:\Python27\lib\site-packages\MySQLdb\cursors.py", line 205, in execute
    self.errorhandler(self, exc, value)
  File "C:\Python27\lib\site-packages\MySQLdb\connections.py", line 36, in defaulterrorhandler
    raise errorclass, errorvalue
IntegrityError: (1062, "Duplicate entry '' for key 'name'")

2018-01-24 16:01:20,092 - dbBaseHelper - 10884 - ERROR - read - sql params [<src.main.master.service.impl.ProjectServiceImpl.ProjectService object at 0x036B47F0>] type is error,must be dict
2018-01-25 15:43:24,108 - dbBaseHelper - 8960 - ERROR - read - select sql:
        select * from interface where projectid=%(projectId)s and groupid=%(groupId)s 
        order by id desc limit %(offset)s,%(limit)s
         args:{'projectId': u'1', 'limit': u'10', 'groupId': u'1', 'offset': u'0'} Exception:Traceback (most recent call last):
  File "C:\Python27\lib\site-packages\src-0.0.1-py2.7.egg\src\main\master\util\dbUtil\dbBaseHelper.py", line 30, in read
    ret = db.read(self.sql,self.args)
  File "C:\Python27\lib\site-packages\src-0.0.1-py2.7.egg\src\main\master\util\dbUtil\dbBaseUtil.py", line 39, in read
    c.execute(sql, args)
  File "C:\Python27\lib\site-packages\MySQLdb\cursors.py", line 205, in execute
    self.errorhandler(self, exc, value)
  File "C:\Python27\lib\site-packages\MySQLdb\connections.py", line 36, in defaulterrorhandler
    raise errorclass, errorvalue
ProgrammingError: (1064, "You have an error in your SQL syntax; check the manual that corresponds to your MySQL server version for the right syntax to use near ''0','10'' at line 2")

2018-01-25 15:55:09,088 - dbBaseHelper - 6004 - ERROR - read - select sql:
        select * from group_info where projectid = %(projectId)s and type= %(type)s and name=%(name)s
         args:{u'type': 0, u'create_userid': 1, u'name': u'center', u'projectid': 1} Exception:Traceback (most recent call last):
  File "C:\Python27\lib\site-packages\src-0.0.1-py2.7.egg\src\main\master\util\dbUtil\dbBaseHelper.py", line 30, in read
    ret = db.read(self.sql,self.args)
  File "C:\Python27\lib\site-packages\src-0.0.1-py2.7.egg\src\main\master\util\dbUtil\dbBaseUtil.py", line 39, in read
    c.execute(sql, args)
  File "C:\Python27\lib\site-packages\MySQLdb\cursors.py", line 185, in execute
    for key, item in args.iteritems())
KeyError: 'projectId'

2018-01-25 15:56:01,099 - dbBaseHelper - 7528 - ERROR - read - select sql:
        select * from group_info where projectid = %(projectId)s and type= %(type)s and name=%(name)s
         args:{u'type': 0, u'create_userid': 1, u'name': u'stu', u'projectid': 1} Exception:Traceback (most recent call last):
  File "C:\Python27\lib\site-packages\src-0.0.1-py2.7.egg\src\main\master\util\dbUtil\dbBaseHelper.py", line 30, in read
    ret = db.read(self.sql,self.args)
  File "C:\Python27\lib\site-packages\src-0.0.1-py2.7.egg\src\main\master\util\dbUtil\dbBaseUtil.py", line 39, in read
    c.execute(sql, args)
  File "C:\Python27\lib\site-packages\MySQLdb\cursors.py", line 185, in execute
    for key, item in args.iteritems())
KeyError: 'projectId'

2018-01-25 16:04:33,140 - dbBaseHelper - 6004 - ERROR - read - select sql:
        select * from group_info where projectid = %(projectId)s and type= %(type)s and name=%(name)s
         args:{u'type': 0, u'create_userid': 1, u'name': u'stu', u'projectid': 1} Exception:Traceback (most recent call last):
  File "C:\Python27\lib\site-packages\src-0.0.1-py2.7.egg\src\main\master\util\dbUtil\dbBaseHelper.py", line 30, in read
    ret = db.read(self.sql,self.args)
  File "C:\Python27\lib\site-packages\src-0.0.1-py2.7.egg\src\main\master\util\dbUtil\dbBaseUtil.py", line 39, in read
    c.execute(sql, args)
  File "C:\Python27\lib\site-packages\MySQLdb\cursors.py", line 185, in execute
    for key, item in args.iteritems())
KeyError: 'projectId'

2018-01-25 16:41:48,474 - dbBaseHelper - 11912 - ERROR - write - write sql:
        insert into group_info (name,create_userid,type,projectid,gmt_create) values (%(name)s,%(userId)s,%(type)s,%(projectId)s,now())
         args:{u'type': 0, u'create_userid': 1, u'name': u'stu', u'projectid': 1} Exception:Traceback (most recent call last):
  File "C:\Python27\lib\site-packages\src-0.0.1-py2.7.egg\src\main\master\util\dbUtil\dbBaseHelper.py", line 58, in write
    db.write(self.sql,self.args,self.is_execute_many)
  File "C:\Python27\lib\site-packages\src-0.0.1-py2.7.egg\src\main\master\util\dbUtil\dbBaseUtil.py", line 54, in write
    ret = c.execute(sql, args)
  File "C:\Python27\lib\site-packages\MySQLdb\cursors.py", line 185, in execute
    for key, item in args.iteritems())
KeyError: 'userId'

2018-01-25 16:42:09,973 - dbBaseHelper - 11912 - ERROR - write - write sql:
        insert into group_info (name,create_userid,type,projectid,gmt_create) values (%(name)s,%(userId)s,%(type)s,%(projectId)s,now())
         args:{u'type': 0, u'userId': 1, u'name': u'stu', u'projectid': 1} Exception:Traceback (most recent call last):
  File "C:\Python27\lib\site-packages\src-0.0.1-py2.7.egg\src\main\master\util\dbUtil\dbBaseHelper.py", line 58, in write
    db.write(self.sql,self.args,self.is_execute_many)
  File "C:\Python27\lib\site-packages\src-0.0.1-py2.7.egg\src\main\master\util\dbUtil\dbBaseUtil.py", line 54, in write
    ret = c.execute(sql, args)
  File "C:\Python27\lib\site-packages\MySQLdb\cursors.py", line 185, in execute
    for key, item in args.iteritems())
KeyError: 'projectId'

2018-01-26 10:10:34,588 - dbBaseHelper - 10164 - ERROR - write - write sql:
        insert into interface (name,url,create_userid,create_username,update_userid,update_username,describe,
        params,success_response,failure_response,method,format,response_type,status,remarks,projectid,groupid,gmt_create) 
        values (%(name)s,%(url),%(create_userid)s,%(create_username)s,%(update_userid)s,%(update_username)s,%(describe)s,
        s%(params)s,%(success_response)s,%(failure_response)s,%(method)s,%(format)s,%(response_type)s,%(status)s,
        %(remarks)s,%(projectid)s,%(groupid)s,now())
         args:{u'create_username': u'jessica', u'success_response': {u'message': u'', u'success': True, u'statusCode': 0}, u'name': u'api/currentUser', u'format': u'application/json', u'url': u'http://localhost:8090/v1/interface/addInterfaceItem', u'failure_response': {u'message': u'', u'success': False, u'statusCode': 0}, u'describe': u'\u65b0\u589e\u521d\u59cb\u5316\u7528\u6237\u63a5\u53e3', u'groupid': 1, u'status': 1, u'params': {u'name': u'', u'address': u''}, u'update_username': u'', u'projectid': 1, u'remarks': u'', u'response_type': u'json', u'create_userid': 1, u'method': u'Get', u'update_userid': 0} Exception:Traceback (most recent call last):
  File "C:\Python27\lib\site-packages\src-0.0.1-py2.7.egg\src\main\master\util\dbUtil\dbBaseHelper.py", line 58, in write
    db.write(self.sql,self.args,self.is_execute_many)
  File "C:\Python27\lib\site-packages\src-0.0.1-py2.7.egg\src\main\master\util\dbUtil\dbBaseUtil.py", line 54, in write
    ret = c.execute(sql, args)
  File "C:\Python27\lib\site-packages\MySQLdb\cursors.py", line 185, in execute
    for key, item in args.iteritems())
ValueError: unsupported format character ',' (0x2c) at index 265

2018-01-26 10:11:18,190 - dbBaseHelper - 9168 - ERROR - write - write sql:
        insert into interface (name,url,create_userid,create_username,update_userid,update_username,describe,
        params,success_response,failure_response,method,format,response_type,status,remarks,projectid,groupid,gmt_create) 
        values (%(name)s,%(url),%(create_userid)s,%(create_username)s,%(update_userid)s,%(update_username)s,%(describe)s,
        s%(params)s,%(success_response)s,%(failure_response)s,%(method)s,%(format)s,%(response_type)s,%(status)s,
        %(remarks)s,%(projectid)s,%(groupid)s,now())
         args:{u'create_username': u'jessica', u'success_response': {u'message': u'', u'success': True, u'statusCode': 0}, u'name': u'api/currentUser', u'format': 1, u'url': u'http://localhost:8090/v1/interface/addInterfaceItem', u'failure_response': {u'message': u'', u'success': False, u'statusCode': 0}, u'describe': u'\u65b0\u589e\u521d\u59cb\u5316\u7528\u6237\u63a5\u53e3', u'groupid': 1, u'status': 1, u'params': {u'name': u'', u'address': u''}, u'update_username': u'', u'projectid': 1, u'remarks': u'', u'response_type': 0, u'create_userid': 1, u'method': u'Get', u'update_userid': 0} Exception:Traceback (most recent call last):
  File "C:\Python27\lib\site-packages\src-0.0.1-py2.7.egg\src\main\master\util\dbUtil\dbBaseHelper.py", line 58, in write
    db.write(self.sql,self.args,self.is_execute_many)
  File "C:\Python27\lib\site-packages\src-0.0.1-py2.7.egg\src\main\master\util\dbUtil\dbBaseUtil.py", line 54, in write
    ret = c.execute(sql, args)
  File "C:\Python27\lib\site-packages\MySQLdb\cursors.py", line 185, in execute
    for key, item in args.iteritems())
ValueError: unsupported format character ',' (0x2c) at index 265

2018-01-26 10:11:41,456 - dbBaseHelper - 9168 - ERROR - write - write sql:
        insert into interface (name,url,create_userid,create_username,update_userid,update_username,describe,
        params,success_response,failure_response,method,format,response_type,status,remarks,projectid,groupid,gmt_create) 
        values (%(name)s,%(url),%(create_userid)s,%(create_username)s,%(update_userid)s,%(update_username)s,%(describe)s,
        s%(params)s,%(success_response)s,%(failure_response)s,%(method)s,%(format)s,%(response_type)s,%(status)s,
        %(remarks)s,%(projectid)s,%(groupid)s,now())
         args:{u'create_username': u'jessica', u'success_response': {u'message': u'', u'success': True, u'statusCode': 0}, u'name': u'api/currentUser', u'format': 1, u'url': u'http://localhost:8090/v1/interface/addInterfaceItem', u'failure_response': {u'message': u'', u'success': False, u'statusCode': 0}, u'describe': u'\u65b0\u589e\u521d\u59cb\u5316\u7528\u6237\u63a5\u53e3', u'groupid': 1, u'status': 1, u'params': {u'name': u'', u'address': u''}, u'update_username': u'', u'projectid': 1, u'remarks': u'', u'response_type': 0, u'create_userid': 1, u'method': u'Get', u'update_userid': 0} Exception:Traceback (most recent call last):
  File "C:\Python27\lib\site-packages\src-0.0.1-py2.7.egg\src\main\master\util\dbUtil\dbBaseHelper.py", line 58, in write
    db.write(self.sql,self.args,self.is_execute_many)
  File "C:\Python27\lib\site-packages\src-0.0.1-py2.7.egg\src\main\master\util\dbUtil\dbBaseUtil.py", line 54, in write
    ret = c.execute(sql, args)
  File "C:\Python27\lib\site-packages\MySQLdb\cursors.py", line 185, in execute
    for key, item in args.iteritems())
ValueError: unsupported format character ',' (0x2c) at index 265

2018-01-26 10:12:05,053 - dbBaseHelper - 10164 - ERROR - write - write sql:
        insert into interface (name,url,create_userid,create_username,update_userid,update_username,describe,
        params,success_response,failure_response,method,format,response_type,status,remarks,projectid,groupid,gmt_create) 
        values (%(name)s,%(url),%(create_userid)s,%(create_username)s,%(update_userid)s,%(update_username)s,%(describe)s,
        s%(params)s,%(success_response)s,%(failure_response)s,%(method)s,%(format)s,%(response_type)s,%(status)s,
        %(remarks)s,%(projectid)s,%(groupid)s,now())
         args:{u'create_username': u'jessica', u'success_response': {u'message': u'', u'success': True, u'statusCode': 0}, u'name': u'api/currentUser', u'format': u'1', u'url': u'http://localhost:8090/v1/interface/addInterfaceItem', u'failure_response': {u'message': u'', u'success': False, u'statusCode': 0}, u'describe': u'\u65b0\u589e\u521d\u59cb\u5316\u7528\u6237\u63a5\u53e3', u'groupid': 1, u'status': 1, u'params': {u'name': u'', u'address': u''}, u'update_username': u'', u'projectid': 1, u'remarks': u'', u'response_type': 0, u'create_userid': 1, u'method': u'Get', u'update_userid': 0} Exception:Traceback (most recent call last):
  File "C:\Python27\lib\site-packages\src-0.0.1-py2.7.egg\src\main\master\util\dbUtil\dbBaseHelper.py", line 58, in write
    db.write(self.sql,self.args,self.is_execute_many)
  File "C:\Python27\lib\site-packages\src-0.0.1-py2.7.egg\src\main\master\util\dbUtil\dbBaseUtil.py", line 54, in write
    ret = c.execute(sql, args)
  File "C:\Python27\lib\site-packages\MySQLdb\cursors.py", line 185, in execute
    for key, item in args.iteritems())
ValueError: unsupported format character ',' (0x2c) at index 265

2018-01-26 10:12:18,842 - dbBaseHelper - 13892 - ERROR - write - write sql:
        insert into interface (name,url,create_userid,create_username,update_userid,update_username,describe,
        params,success_response,failure_response,method,format,response_type,status,remarks,projectid,groupid,gmt_create) 
        values (%(name)s,%(url),%(create_userid)s,%(create_username)s,%(update_userid)s,%(update_username)s,%(describe)s,
        s%(params)s,%(success_response)s,%(failure_response)s,%(method)s,%(format)s,%(response_type)s,%(status)s,
        %(remarks)s,%(projectid)s,%(groupid)s,now())
         args:{u'create_username': u'jessica', u'success_response': {u'message': u'', u'success': True, u'statusCode': 0}, u'name': u'api/currentUser', u'format': u'1', u'url': u'http://localhost:8090/v1/interface/addInterfaceItem', u'failure_response': {u'message': u'', u'success': False, u'statusCode': 0}, u'describe': u'\u65b0\u589e\u521d\u59cb\u5316\u7528\u6237\u63a5\u53e3', u'groupid': 1, u'status': 1, u'params': {u'name': u'', u'address': u''}, u'update_username': u'', u'projectid': 1, u'remarks': u'', u'response_type': 0, u'create_userid': 1, u'method': u'Get', u'update_userid': 0} Exception:Traceback (most recent call last):
  File "C:\Python27\lib\site-packages\src-0.0.1-py2.7.egg\src\main\master\util\dbUtil\dbBaseHelper.py", line 58, in write
    db.write(self.sql,self.args,self.is_execute_many)
  File "C:\Python27\lib\site-packages\src-0.0.1-py2.7.egg\src\main\master\util\dbUtil\dbBaseUtil.py", line 54, in write
    ret = c.execute(sql, args)
  File "C:\Python27\lib\site-packages\MySQLdb\cursors.py", line 185, in execute
    for key, item in args.iteritems())
ValueError: unsupported format character ',' (0x2c) at index 265

2018-01-26 10:13:13,865 - dbBaseHelper - 9168 - ERROR - write - write sql:
        insert into interface (name,url,create_userid,create_username,update_userid,update_username,describe,
        params,success_response,failure_response,method,format,response_type,status,remarks,projectid,groupid,gmt_create) 
        values (%(name)s,%(url),%(create_userid)s,%(create_username)s,%(update_userid)s,%(update_username)s,%(describe)s,
        s%(params)s,%(success_response)s,%(failure_response)s,%(method)s,%(format)s,%(response_type)s,%(status)s,
        %(remarks)s,%(projectid)s,%(groupid)s,now())
         args:{u'create_username': u'jessica', u'success_response': {u'message': u'', u'success': True, u'statusCode': 0}, u'name': u'api/currentUser', u'format': u'1', u'url': u'http://localhost:8090/v1/interface/addInterfaceItem', u'failure_response': {u'message': u'', u'success': False, u'statusCode': 0}, u'describe': u'\u65b0\u589e\u521d\u59cb\u5316\u7528\u6237\u63a5\u53e3', u'groupid': 1, u'status': 1, u'params': {u'name': u'', u'address': u''}, u'update_username': u'', u'projectid': 1, u'remarks': u'', u'response_type': 0, u'create_userid': 1, u'method': u'Get', u'update_userid': 0} Exception:Traceback (most recent call last):
  File "C:\Python27\lib\site-packages\src-0.0.1-py2.7.egg\src\main\master\util\dbUtil\dbBaseHelper.py", line 58, in write
    db.write(self.sql,self.args,self.is_execute_many)
  File "C:\Python27\lib\site-packages\src-0.0.1-py2.7.egg\src\main\master\util\dbUtil\dbBaseUtil.py", line 54, in write
    ret = c.execute(sql, args)
  File "C:\Python27\lib\site-packages\MySQLdb\cursors.py", line 185, in execute
    for key, item in args.iteritems())
ValueError: unsupported format character ',' (0x2c) at index 265

2018-01-26 10:14:53,247 - dbBaseHelper - 13652 - ERROR - write - write sql:
        insert into interface (name,url,create_userid,create_username,update_userid,update_username,describe,
        params,success_response,failure_response,method,format,response_type,status,remarks,projectid,groupid,gmt_create) 
        values (%(name)s,%(url),%(create_userid)s,%(create_username)s,%(update_userid)s,%(update_username)s,%(describe)s,
        s%(params)s,%(success_response)s,%(failure_response)s,%(method)s,%(format)s,%(response_type)s,%(status)s,
        %(remarks)s,%(projectid)s,%(groupid)s,now())
         args:{u'create_username': u'jessica', u'success_response': {u'message': u'', u'success': True, u'statusCode': 0}, u'name': u'api/currentUser', u'format': u'1', u'url': u'http://localhost:8090/v1/interface/addInterfaceItem', u'failure_response': {u'message': u'', u'success': False, u'statusCode': 0}, u'describe': u'\u65b0\u589e\u521d\u59cb\u5316\u7528\u6237\u63a5\u53e3', u'groupid': 1, u'status': 1, u'params': {u'name': u'', u'address': u''}, u'update_username': u'', u'projectid': 1, u'remarks': u'', u'response_type': 0, u'create_userid': 1, u'method': 0, u'update_userid': 0} Exception:Traceback (most recent call last):
  File "C:\Python27\lib\site-packages\src-0.0.1-py2.7.egg\src\main\master\util\dbUtil\dbBaseHelper.py", line 58, in write
    db.write(self.sql,self.args,self.is_execute_many)
  File "C:\Python27\lib\site-packages\src-0.0.1-py2.7.egg\src\main\master\util\dbUtil\dbBaseUtil.py", line 54, in write
    ret = c.execute(sql, args)
  File "C:\Python27\lib\site-packages\MySQLdb\cursors.py", line 185, in execute
    for key, item in args.iteritems())
ValueError: unsupported format character ',' (0x2c) at index 265

2018-01-26 10:21:53,207 - dbBaseHelper - 12644 - ERROR - write - write sql:
        insert into interface (name,url,create_userid,create_username,update_userid,update_username,describe,
        params,success_response,failure_response,method,format,response_type,status,remarks,projectid,groupid,gmt_create) 
        values (%(name)s,%(url),%(create_userid)s,%(create_username)s,%(update_userid)s,%(update_username)s,%(describe)s,
        s%(params)s,%(success_response)s,%(failure_response)s,%(method)s,%(format)s,%(response_type)s,%(status)s,
        %(remarks)s,%(projectid)s,%(groupid)s,now())
         args:{u'create_username': u'jessica', u'success_response': {u'message': u'', u'success': True, u'statusCode': 0}, u'name': u'api/currentUser', u'format': u'1', u'url': u'http://localhost:8090/v1/interface/addInterfaceItem', u'failure_response': {u'message': u'', u'success': False, u'statusCode': 0}, u'describe': u'\u65b0\u589e\u521d\u59cb\u5316\u7528\u6237\u63a5\u53e3', u'groupid': 1, u'status': 1, u'params': {u'name': u'', u'address': u''}, u'update_username': u'', u'projectid': 1, u'remarks': u'', u'response_type': 0, u'create_userid': 1, u'method': 0, u'update_userid': 0} Exception:Traceback (most recent call last):
  File "C:\Python27\lib\site-packages\src-0.0.1-py2.7.egg\src\main\master\util\dbUtil\dbBaseHelper.py", line 58, in write
    db.write(self.sql,self.args,self.is_execute_many)
  File "C:\Python27\lib\site-packages\src-0.0.1-py2.7.egg\src\main\master\util\dbUtil\dbBaseUtil.py", line 54, in write
    ret = c.execute(sql, args)
  File "C:\Python27\lib\site-packages\MySQLdb\cursors.py", line 185, in execute
    for key, item in args.iteritems())
ValueError: unsupported format character ',' (0x2c) at index 265

2018-01-26 10:36:34,632 - dbBaseHelper - 12644 - ERROR - write - write sql:
        insert into interface (name,url,create_userid,create_username,update_userid,update_username,describe,
        params,success_response,failure_response,method,format,response_type,status,remarks,projectid,groupid,gmt_create) 
        values (%(name)s,%(url),%(create_userid)s,%(create_username)s,%(update_userid)s,%(update_username)s,%(describe)s,
        s%(params)s,%(success_response)s,%(failure_response)s,%(method)s,%(format)s,%(response_type)s,%(status)s,
        %(remarks)s,%(projectid)s,%(groupid)s,now())
         args:{u'create_username': u'jessica', u'success_response': {u'message': u'', u'success': True, u'statusCode': 0}, u'name': u'api/currentUser', u'format': u'1', u'url': u'http://localhost:8090/v1/interface/addInterfaceItem', u'failure_response': {u'message': u'', u'success': False, u'statusCode': 0}, u'describe': u'test,test', u'groupid': 1, u'status': 1, u'params': {u'name': u'', u'address': u''}, u'update_username': u'', u'projectid': 1, u'remarks': u'', u'response_type': 0, u'create_userid': 1, u'method': 0, u'update_userid': 0} Exception:Traceback (most recent call last):
  File "C:\Python27\lib\site-packages\src-0.0.1-py2.7.egg\src\main\master\util\dbUtil\dbBaseHelper.py", line 58, in write
    db.write(self.sql,self.args,self.is_execute_many)
  File "C:\Python27\lib\site-packages\src-0.0.1-py2.7.egg\src\main\master\util\dbUtil\dbBaseUtil.py", line 54, in write
    ret = c.execute(sql, args)
  File "C:\Python27\lib\site-packages\MySQLdb\cursors.py", line 185, in execute
    for key, item in args.iteritems())
ValueError: unsupported format character ',' (0x2c) at index 265

2018-01-26 10:43:05,290 - dbBaseHelper - 12644 - ERROR - write - write sql:
        insert into interface (name,url,create_userid,create_username,update_userid,update_username,describe,
        params,success_response,failure_response,method,format,response_type,status,remarks,projectid,groupid,gmt_create) 
        values (%(name)s,%(url),%(create_userid)s,%(create_username)s,%(update_userid)s,%(update_username)s,%(describe)s,
        s%(params)s,%(success_response)s,%(failure_response)s,%(method)s,%(format)s,%(response_type)s,%(status)s,
        %(remarks)s,%(projectid)s,%(groupid)s,now())
         args:{u'create_username': u'jessica', u'success_response': {u'message': u'', u'success': True, u'statusCode': 0}, u'name': u'api/currentUser', u'format': u'1', u'url': u'interface/addInterfaceItem', u'failure_response': {u'message': u'', u'success': False, u'statusCode': 0}, u'describe': u'test,test', u'groupid': 1, u'status': 1, u'params': {u'name': u'', u'address': u''}, u'update_username': u'', u'projectid': 1, u'remarks': u'', u'response_type': 0, u'create_userid': 1, u'method': 0, u'update_userid': 0} Exception:Traceback (most recent call last):
  File "C:\Python27\lib\site-packages\src-0.0.1-py2.7.egg\src\main\master\util\dbUtil\dbBaseHelper.py", line 58, in write
    db.write(self.sql,self.args,self.is_execute_many)
  File "C:\Python27\lib\site-packages\src-0.0.1-py2.7.egg\src\main\master\util\dbUtil\dbBaseUtil.py", line 54, in write
    ret = c.execute(sql, args)
  File "C:\Python27\lib\site-packages\MySQLdb\cursors.py", line 185, in execute
    for key, item in args.iteritems())
ValueError: unsupported format character ',' (0x2c) at index 265

2018-01-26 10:43:29,217 - dbBaseHelper - 14284 - ERROR - write - write sql:
        insert into interface (name,url,create_userid,create_username,update_userid,update_username,describe,
        params,success_response,failure_response,method,format,response_type,status,remarks,projectid,groupid,gmt_create) 
        values (%(name)s,%(url),%(create_userid)s,%(create_username)s,%(update_userid)s,%(update_username)s,%(describe)s,
        s%(params)s,%(success_response)s,%(failure_response)s,%(method)s,%(format)s,%(response_type)s,%(status)s,
        %(remarks)s,%(projectid)s,%(groupid)s,now())
         args:{u'create_username': u'jessica', u'success_response': {u'message': u'', u'success': True, u'statusCode': 0}, u'name': u'api/currentUser', u'format': u'1', u'url': u'interface/addInterfaceItem', u'failure_response': {u'message': u'', u'success': False, u'statusCode': 0}, u'describe': u'test,test', u'groupid': 1, u'status': 1, u'params': {u'name': u'', u'address': u''}, u'update_username': u'', u'projectid': 1, u'remarks': u'', u'response_type': 0, u'create_userid': 1, u'method': 0, u'update_userid': 0} Exception:Traceback (most recent call last):
  File "C:\Python27\lib\site-packages\src-0.0.1-py2.7.egg\src\main\master\util\dbUtil\dbBaseHelper.py", line 58, in write
    db.write(self.sql,self.args,self.is_execute_many)
  File "C:\Python27\lib\site-packages\src-0.0.1-py2.7.egg\src\main\master\util\dbUtil\dbBaseUtil.py", line 54, in write
    ret = c.execute(sql, args)
  File "C:\Python27\lib\site-packages\MySQLdb\cursors.py", line 185, in execute
    for key, item in args.iteritems())
ValueError: unsupported format character ',' (0x2c) at index 265

2018-01-26 10:46:34,640 - dbBaseHelper - 12644 - ERROR - read - select sql:
        select * from interface where projectid=%(projectId)s and groupid=%(groupId)s 
        order by id desc limit %(offset)s,%(limit)s
         args:{'projectId': u'1', 'limit': u'10', 'groupId': u'1', 'offset': u'0'} Exception:Traceback (most recent call last):
  File "C:\Python27\lib\site-packages\src-0.0.1-py2.7.egg\src\main\master\util\dbUtil\dbBaseHelper.py", line 30, in read
    ret = db.read(self.sql,self.args)
  File "C:\Python27\lib\site-packages\src-0.0.1-py2.7.egg\src\main\master\util\dbUtil\dbBaseUtil.py", line 39, in read
    c.execute(sql, args)
  File "C:\Python27\lib\site-packages\MySQLdb\cursors.py", line 205, in execute
    self.errorhandler(self, exc, value)
  File "C:\Python27\lib\site-packages\MySQLdb\connections.py", line 36, in defaulterrorhandler
    raise errorclass, errorvalue
ProgrammingError: (1064, "You have an error in your SQL syntax; check the manual that corresponds to your MySQL server version for the right syntax to use near ''0','10'' at line 2")

2018-01-26 10:46:53,168 - dbBaseHelper - 5940 - ERROR - read - select sql:
        select * from interface where projectid=%(projectId)s and groupid=%(groupId)s 
        order by id desc limit %(offset)s,%(limit)s
         args:{'projectId': u'1', 'limit': u'10', 'groupId': u'1', 'offset': u'1'} Exception:Traceback (most recent call last):
  File "C:\Python27\lib\site-packages\src-0.0.1-py2.7.egg\src\main\master\util\dbUtil\dbBaseHelper.py", line 30, in read
    ret = db.read(self.sql,self.args)
  File "C:\Python27\lib\site-packages\src-0.0.1-py2.7.egg\src\main\master\util\dbUtil\dbBaseUtil.py", line 39, in read
    c.execute(sql, args)
  File "C:\Python27\lib\site-packages\MySQLdb\cursors.py", line 205, in execute
    self.errorhandler(self, exc, value)
  File "C:\Python27\lib\site-packages\MySQLdb\connections.py", line 36, in defaulterrorhandler
    raise errorclass, errorvalue
ProgrammingError: (1064, "You have an error in your SQL syntax; check the manual that corresponds to your MySQL server version for the right syntax to use near ''1','10'' at line 2")

2018-01-26 10:50:29,645 - dbBaseHelper - 14284 - ERROR - read - select sql:
        select * from interface where projectid=%(projectId)s and groupid=%(groupId)s 
        order by id desc limit %(offset)s,%(limit)s
         args:{'projectId': u'1', 'limit': u'10', 'groupId': u'1', 'offset': u'0'} Exception:Traceback (most recent call last):
  File "C:\Python27\lib\site-packages\src-0.0.1-py2.7.egg\src\main\master\util\dbUtil\dbBaseHelper.py", line 30, in read
    ret = db.read(self.sql,self.args)
  File "C:\Python27\lib\site-packages\src-0.0.1-py2.7.egg\src\main\master\util\dbUtil\dbBaseUtil.py", line 39, in read
    c.execute(sql, args)
  File "C:\Python27\lib\site-packages\MySQLdb\cursors.py", line 205, in execute
    self.errorhandler(self, exc, value)
  File "C:\Python27\lib\site-packages\MySQLdb\connections.py", line 36, in defaulterrorhandler
    raise errorclass, errorvalue
ProgrammingError: (1064, "You have an error in your SQL syntax; check the manual that corresponds to your MySQL server version for the right syntax to use near ''0','10'' at line 2")

2018-01-26 10:51:38,407 - dbBaseHelper - 14040 - ERROR - read - select sql:
        select * from interface where projectid=%(projectId)s and groupid=%(groupId)s 
        order by id desc limit %(offset)s,%(limit)s
         args:{'projectId': u'', 'limit': u'', 'groupId': u'', 'offset': u''} Exception:Traceback (most recent call last):
  File "C:\Python27\lib\site-packages\src-0.0.1-py2.7.egg\src\main\master\util\dbUtil\dbBaseHelper.py", line 30, in read
    ret = db.read(self.sql,self.args)
  File "C:\Python27\lib\site-packages\src-0.0.1-py2.7.egg\src\main\master\util\dbUtil\dbBaseUtil.py", line 39, in read
    c.execute(sql, args)
  File "C:\Python27\lib\site-packages\MySQLdb\cursors.py", line 205, in execute
    self.errorhandler(self, exc, value)
  File "C:\Python27\lib\site-packages\MySQLdb\connections.py", line 36, in defaulterrorhandler
    raise errorclass, errorvalue
ProgrammingError: (1064, "You have an error in your SQL syntax; check the manual that corresponds to your MySQL server version for the right syntax to use near ''',''' at line 2")

2018-01-26 10:51:53,530 - dbBaseHelper - 7504 - ERROR - read - select sql:
        select * from interface where projectid=%(projectId)s and groupid=%(groupId)s 
        order by id desc limit %(offset)s,%(limit)s
         args:{'projectId': u'1', 'limit': u'10', 'groupId': u'1', 'offset': u'0'} Exception:Traceback (most recent call last):
  File "C:\Python27\lib\site-packages\src-0.0.1-py2.7.egg\src\main\master\util\dbUtil\dbBaseHelper.py", line 30, in read
    ret = db.read(self.sql,self.args)
  File "C:\Python27\lib\site-packages\src-0.0.1-py2.7.egg\src\main\master\util\dbUtil\dbBaseUtil.py", line 39, in read
    c.execute(sql, args)
  File "C:\Python27\lib\site-packages\MySQLdb\cursors.py", line 205, in execute
    self.errorhandler(self, exc, value)
  File "C:\Python27\lib\site-packages\MySQLdb\connections.py", line 36, in defaulterrorhandler
    raise errorclass, errorvalue
ProgrammingError: (1064, "You have an error in your SQL syntax; check the manual that corresponds to your MySQL server version for the right syntax to use near ''0','10'' at line 2")

2018-02-11 15:29:25,450 - dbBaseHelper - 7820 - ERROR - write - write sql:
        insert into interface (name,url,create_userid,create_username,update_userid,update_username,describe,
        params,success_response,failure_response,method,format,response_type,status,remarks,projectid,groupid,gmt_create) 
        values (%(name)s,%(url),%(create_userid)s,%(create_username)s,%(update_userid)s,%(update_username)s,%(describe)s,
        s%(params)s,%(success_response)s,%(failure_response)s,%(method)s,%(format)s,%(response_type)s,%(status)s,
        %(remarks)s,%(projectid)s,%(groupid)s,now())
         args:{u'create_username': u'jessica', u'success_response': {u'message': u'', u'success': True, u'statusCode': 0}, u'name': u'api/currentUser', u'format': u'1', u'url': u'interface/addInterfaceItem', u'failure_response': {u'message': u'', u'success': False, u'statusCode': 0}, u'describe': u'test,test', u'groupid': 1, u'status': 1, u'params': {u'name': u'', u'address': u''}, u'update_username': u'', u'projectid': 1, u'remarks': u'', u'response_type': 0, u'create_userid': 1, u'method': 0, u'update_userid': 0} Exception:Traceback (most recent call last):
  File "C:\Python27\lib\site-packages\src-0.0.1-py2.7.egg\src\main\master\util\dbUtil\dbBaseHelper.py", line 58, in write
    db.write(self.sql,self.args,self.is_execute_many)
  File "C:\Python27\lib\site-packages\src-0.0.1-py2.7.egg\src\main\master\util\dbUtil\dbBaseUtil.py", line 54, in write
    ret = c.execute(sql, args)
  File "C:\Python27\lib\site-packages\MySQLdb\cursors.py", line 185, in execute
    for key, item in args.iteritems())
ValueError: unsupported format character ',' (0x2c) at index 265

2018-02-11 15:29:52,911 - dbBaseHelper - 7820 - ERROR - read - select sql:
        select * from interface where projectid=%(projectId)s and groupid=%(groupId)s 
        order by id desc limit %(offset)s,%(limit)s
         args:{'projectId': u'1', 'limit': u'10', 'groupId': u'1', 'offset': u'0'} Exception:Traceback (most recent call last):
  File "C:\Python27\lib\site-packages\src-0.0.1-py2.7.egg\src\main\master\util\dbUtil\dbBaseHelper.py", line 30, in read
    ret = db.read(self.sql,self.args)
  File "C:\Python27\lib\site-packages\src-0.0.1-py2.7.egg\src\main\master\util\dbUtil\dbBaseUtil.py", line 39, in read
    c.execute(sql, args)
  File "C:\Python27\lib\site-packages\MySQLdb\cursors.py", line 205, in execute
    self.errorhandler(self, exc, value)
  File "C:\Python27\lib\site-packages\MySQLdb\connections.py", line 36, in defaulterrorhandler
    raise errorclass, errorvalue
ProgrammingError: (1064, "You have an error in your SQL syntax; check the manual that corresponds to your MySQL server version for the right syntax to use near ''0','10'' at line 2")

2018-02-11 15:31:38,081 - dbBaseHelper - 7200 - ERROR - write - write sql:
        delete from project where id = %(projectId)s
         args:{u'id': 5} Exception:Traceback (most recent call last):
  File "C:\Python27\lib\site-packages\src-0.0.1-py2.7.egg\src\main\master\util\dbUtil\dbBaseHelper.py", line 58, in write
    db.write(self.sql,self.args,self.is_execute_many)
  File "C:\Python27\lib\site-packages\src-0.0.1-py2.7.egg\src\main\master\util\dbUtil\dbBaseUtil.py", line 54, in write
    ret = c.execute(sql, args)
  File "C:\Python27\lib\site-packages\MySQLdb\cursors.py", line 185, in execute
    for key, item in args.iteritems())
KeyError: 'projectId'

2018-02-11 17:50:42,746 - dbBaseHelper - 8032 - ERROR - write - write sql:
        update group_info set name=%(name)s where id=%(groupId)s
         args:{u'name': u'test_consult', u'id': 3} Exception:Traceback (most recent call last):
  File "C:\Python27\lib\site-packages\src-0.0.1-py2.7.egg\src\main\master\util\dbUtil\dbBaseHelper.py", line 58, in write
    db.write(self.sql,self.args,self.is_execute_many)
  File "C:\Python27\lib\site-packages\src-0.0.1-py2.7.egg\src\main\master\util\dbUtil\dbBaseUtil.py", line 54, in write
    ret = c.execute(sql, args)
  File "C:\Python27\lib\site-packages\MySQLdb\cursors.py", line 185, in execute
    for key, item in args.iteritems())
KeyError: 'groupId'

2018-02-11 18:14:36,361 - dbBaseHelper - 5468 - ERROR - write - write sql:
        insert into interface (name,url,create_userid,create_username,update_userid,update_username,describe,
        params,success_response,failure_response,method,format,response_type,status,remarks,projectid,groupid,gmt_create) 
        values (%(name)s,%(url),%(create_userid)s,%(create_username)s,%(update_userid)s,%(update_username)s,%(describe)s,
        s%(params)s,%(success_response)s,%(failure_response)s,%(method)s,%(format)s,%(response_type)s,%(status)s,
        %(remarks)s,%(projectid)s,%(groupid)s,now())
         args:{u'status': 1, u'success_response': {u'message': [{u'name': u'SchoolpalShow'}], u'success': u'true', u'statusCode': 0}, u'name': u'interface1', u'format': 1, u'url': u'v1/interface/addInterfaceItem', u'failure_response': {u'message': [{u'name': u''}], u'success': u'false', u'statusCode': 0}, u'describe': u'the first interface', u'groupid': 1, u'params': {u'id': 1}, u'response_type': 0, u'projectid': 1, u'remarks': u'remarks', u'create_userid': 1, u'method': 1} Exception:Traceback (most recent call last):
  File "C:\Python27\lib\site-packages\src-0.0.1-py2.7.egg\src\main\master\util\dbUtil\dbBaseHelper.py", line 58, in write
    db.write(self.sql,self.args,self.is_execute_many)
  File "C:\Python27\lib\site-packages\src-0.0.1-py2.7.egg\src\main\master\util\dbUtil\dbBaseUtil.py", line 54, in write
    ret = c.execute(sql, args)
  File "C:\Python27\lib\site-packages\MySQLdb\cursors.py", line 185, in execute
    for key, item in args.iteritems())
  File "C:\Python27\lib\site-packages\MySQLdb\cursors.py", line 185, in <genexpr>
    for key, item in args.iteritems())
  File "C:\Python27\lib\site-packages\MySQLdb\connections.py", line 278, in literal
    return self.escape(o, self.encoders)
  File "C:\Python27\lib\site-packages\MySQLdb\converters.py", line 133, in quote_tuple
    return "(%s)" % (','.join(escape_sequence(t, d)))
TypeError: sequence item 0: expected string, dict found

2018-02-11 18:18:20,512 - dbBaseHelper - 6736 - ERROR - write - write sql:
        insert into interface (name,url,create_userid,create_username,update_userid,update_username,describe,
        params,success_response,failure_response,method,format,response_type,status,remarks,projectid,groupid,gmt_create) 
        values (%(name)s,%(url),%(create_userid)s,%(create_username)s,%(update_userid)s,%(update_username)s,%(describe)s,
        s%(params)s,%(success_response)s,%(failure_response)s,%(method)s,%(format)s,%(response_type)s,%(status)s,
        %(remarks)s,%(projectid)s,%(groupid)s,now())
         args:{u'status': 1, u'success_response': {u'success': u'true', u'statusCode': 0}, u'name': u'interface1', u'format': 1, u'url': u'v1/interface/addInterfaceItem', u'failure_response': {u'success': u'false', u'statusCode': 0}, u'describe': u'the first interface', u'groupid': 1, u'params': {u'id': 1}, u'response_type': 0, u'projectid': 1, u'remarks': u'remarks', u'create_userid': 1, u'method': 1} Exception:Traceback (most recent call last):
  File "C:\Python27\lib\site-packages\src-0.0.1-py2.7.egg\src\main\master\util\dbUtil\dbBaseHelper.py", line 58, in write
    db.write(self.sql,self.args,self.is_execute_many)
  File "C:\Python27\lib\site-packages\src-0.0.1-py2.7.egg\src\main\master\util\dbUtil\dbBaseUtil.py", line 54, in write
    ret = c.execute(sql, args)
  File "C:\Python27\lib\site-packages\MySQLdb\cursors.py", line 185, in execute
    for key, item in args.iteritems())
ValueError: unsupported format character ',' (0x2c) at index 265

2018-02-11 18:21:14,469 - dbBaseHelper - 5468 - ERROR - write - write sql:
        insert into interface (name,url,create_userid,create_username,update_userid,update_username,describe,
        params,success_response,failure_response,method,format,response_type,status,remarks,projectid,groupid,gmt_create) 
        values (%(name)s,%(url),%(create_userid)s,%(create_username)s,%(update_userid)s,%(update_username)s,%(describe)s,
        s%(params)s,%(success_response)s,%(failure_response)s,%(method)s,%(format)s,%(response_type)s,%(status)s,
        %(remarks)s,%(projectid)s,%(groupid)s,now())
         args:{u'status': 1, u'success_response': {u'success': u'true', u'statusCode': 0}, u'name': u'interface1', u'format': 1, u'url': u'v1/interface/addInterfaceItem', u'failure_response': {u'success': u'false', u'statusCode': 0}, u'describe': u'the first interface', u'groupid': 1, u'params': {u'id': 1}, u'response_type': 0, u'projectid': 1, u'remarks': u'remarks', u'create_userid': 1, u'method': 1} Exception:Traceback (most recent call last):
  File "C:\Python27\lib\site-packages\src-0.0.1-py2.7.egg\src\main\master\util\dbUtil\dbBaseHelper.py", line 58, in write
    db.write(self.sql,self.args,self.is_execute_many)
  File "C:\Python27\lib\site-packages\src-0.0.1-py2.7.egg\src\main\master\util\dbUtil\dbBaseUtil.py", line 54, in write
    ret = c.execute(sql, args)
  File "C:\Python27\lib\site-packages\MySQLdb\cursors.py", line 185, in execute
    for key, item in args.iteritems())
ValueError: unsupported format character ',' (0x2c) at index 265

2018-02-12 15:20:50,931 - dbBaseHelper - 9460 - ERROR - write - write sql:
        insert into interface (name,url,create_userid,create_username,update_userid,update_username,describe,
        params,success_response,failure_response,method,format,response_type,status,remarks,projectid,groupid,gmt_create) 
        values (%(name)s,%(url),%(create_userid)s,%(create_username)s,%(update_userid)s,%(update_username)s,%(describe)s,
        s%(params)s,%(success_response)s,%(failure_response)s,%(method)s,%(format)s,%(response_type)s,%(status)s,
        %(remarks)s,%(projectid)s,%(groupid)s,now())
         args:{u'status': 1, u'success_response': {u'success': u'true', u'statusCode': 0}, u'name': u'interface1', u'format': 1, u'url': u'v1/interface/addInterfaceItem', u'failure_response': {u'success': u'false', u'statusCode': 0}, u'describe': u'the first interface', u'groupid': 1, u'params': {u'id': 1}, u'response_type': 0, u'projectid': 1, u'remarks': u'remarks', u'create_userid': 1, u'method': 1} Exception:Traceback (most recent call last):
  File "C:\Python27\lib\site-packages\src-0.0.1-py2.7.egg\src\main\master\util\dbUtil\dbBaseHelper.py", line 58, in write
    db.write(self.sql,self.args,self.is_execute_many)
  File "C:\Python27\lib\site-packages\src-0.0.1-py2.7.egg\src\main\master\util\dbUtil\dbBaseUtil.py", line 54, in write
    ret = c.execute(sql, args)
  File "C:\Python27\lib\site-packages\MySQLdb\cursors.py", line 185, in execute
    for key, item in args.iteritems())
ValueError: unsupported format character ',' (0x2c) at index 265

2018-02-12 15:47:31,825 - dbBaseHelper - 7600 - ERROR - write - write sql:
        insert into interface (name,url,create_userid,create_username,update_userid,update_username,describe,
        params,success_response,failure_response,method,format,response_type,status,remarks,projectid,groupid,gmt_create) 
        values (%(name)s,%(url),%(create_userid)s,%(create_username)s,%(update_userid)s,%(update_username)s,%(describe)s,
        %(params)s,%(success_response)s,%(failure_response)s,%(method)s,%(format)s,%(response_type)s,%(status)s,
        %(remarks)s,%(projectid)s,%(groupid)s,now())
         args:{u'status': 1, u'success_response': {u'success': u'true', u'statusCode': 0}, u'name': u'interface1', u'format': 1, u'url': u'v1/interface/addInterfaceItem', u'failure_response': {u'success': u'false', u'statusCode': 0}, u'describe': u'the first interface', u'groupid': 1, u'params': {u'id': 1}, u'response_type': 0, u'projectid': 1, u'remarks': u'remarks', u'create_userid': 1, u'method': 1} Exception:Traceback (most recent call last):
  File "C:\Python27\lib\site-packages\src-0.0.1-py2.7.egg\src\main\master\util\dbUtil\dbBaseHelper.py", line 58, in write
    db.write(self.sql,self.args,self.is_execute_many)
  File "C:\Python27\lib\site-packages\src-0.0.1-py2.7.egg\src\main\master\util\dbUtil\dbBaseUtil.py", line 54, in write
    ret = c.execute(sql, args)
  File "C:\Python27\lib\site-packages\MySQLdb\cursors.py", line 185, in execute
    for key, item in args.iteritems())
ValueError: unsupported format character ',' (0x2c) at index 265

2018-02-23 10:16:51,062 - dbBaseHelper - 5668 - ERROR - write - write sql:
        insert into interface (name,url,create_userid,create_username,update_userid,update_username,describe,
        params,success_response,failure_response,method,format,response_type,status,remarks,projectid,groupid,gmt_create) 
        values (%(name)s,%(url),%(create_userid)s,%(create_username)s,%(update_userid)s,%(update_username)s,%(describe)s,
        %(params)s,%(success_response)s,%(failure_response)s,%(method)s,%(format)s,%(response_type)s,%(status)s,
        %(remarks)s,%(projectid)s,%(groupid)s,now())
         args:{u'status': 1, u'success_response': {u'success': u'true', u'statusCode': 0}, u'name': u'interface1', u'format': 1, u'url': u'v1/interface/addInterfaceItem', u'failure_response': {u'success': u'false', u'statusCode': 0}, u'describe': u'the first interface', u'groupid': 1, u'params': {u'id': 1}, u'response_type': 0, u'projectid': 1, u'remarks': u'remarks', u'create_userid': 1, u'method': 1} Exception:Traceback (most recent call last):
  File "C:\Python27\lib\site-packages\src-0.0.1-py2.7.egg\src\main\master\util\dbUtil\dbBaseHelper.py", line 58, in write
    db.write(self.sql,self.args,self.is_execute_many)
  File "C:\Python27\lib\site-packages\src-0.0.1-py2.7.egg\src\main\master\util\dbUtil\dbBaseUtil.py", line 54, in write
    ret = c.execute(sql, args)
  File "C:\Python27\lib\site-packages\MySQLdb\cursors.py", line 185, in execute
    for key, item in args.iteritems())
ValueError: unsupported format character ',' (0x2c) at index 265

2018-02-23 10:34:07,286 - dbBaseHelper - 5668 - ERROR - write - write sql:
        insert into interface (name,url,create_userid,create_username,update_userid,update_username,describe,
        params,success_response,failure_response,method,format,response_type,status,remarks,projectid,groupid,gmt_create) 
        values (%(name)s,%(url),%(create_userid)s,%(create_username)s,%(update_userid)s,%(update_username)s,%(describe)s,
        %(params)s,%(success_response)s,%(failure_response)s,%(method)s,%(format)s,%(response_type)s,%(status)s,
        %(remarks)s,%(projectid)s,%(groupid)s,now())
         args:{u'status': 1, u'success_response': {u'success': u'true', u'statusCode': 0}, u'name': u'interface1', u'format': 1, u'url': u'v1/interface/addInterfaceItem', u'failure_response': {u'success': u'false', u'statusCode': 0}, u'describe': u'the first interface', u'groupid': 1, u'params': {u'id': 1}, u'response_type': 0, u'projectid': 1, u'remarks': u'remarks', u'create_userid': 1, u'method': 1} Exception:Traceback (most recent call last):
  File "C:\Python27\lib\site-packages\src-0.0.1-py2.7.egg\src\main\master\util\dbUtil\dbBaseHelper.py", line 58, in write
    db.write(self.sql,self.args,self.is_execute_many)
  File "C:\Python27\lib\site-packages\src-0.0.1-py2.7.egg\src\main\master\util\dbUtil\dbBaseUtil.py", line 54, in write
    ret = c.execute(sql, args)
  File "C:\Python27\lib\site-packages\MySQLdb\cursors.py", line 185, in execute
    for key, item in args.iteritems())
ValueError: unsupported format character ',' (0x2c) at index 265

2018-02-23 10:59:00,427 - dbBaseHelper - 6516 - ERROR - write - write sql:
        insert into interface (name,url,create_userid,create_username,update_userid,update_username,describe,
        params,success_response,failure_response,method,format,response_type,status,remarks,projectid,groupid,gmt_create) 
        values (%(name)s,%(url)s,%(create_userid)s,%(create_username)s,%(update_userid)s,%(update_username)s,%(describe)s,
        %(params)s,%(success_response)s,%(failure_response)s,%(method)s,%(format)s,%(response_type)s,%(status)s,
        %(remarks)s,%(projectid)s,%(groupid)s,now())
         args:{u'status': 1, u'success_response': {u'success': u'true', u'statusCode': 0}, u'name': u'interface1', u'format': 1, u'url': u'v1/interface/addInterfaceItem', u'failure_response': {u'success': u'false', u'statusCode': 0}, u'describe': u'the first interface', u'groupid': 1, u'params': {u'id': 1}, u'response_type': 0, u'projectid': 1, u'remarks': u'remarks', u'create_userid': 1, u'method': 1} Exception:Traceback (most recent call last):
  File "C:\Python27\lib\site-packages\src-0.0.1-py2.7.egg\src\main\master\util\dbUtil\dbBaseHelper.py", line 58, in write
    db.write(self.sql,self.args,self.is_execute_many)
  File "C:\Python27\lib\site-packages\src-0.0.1-py2.7.egg\src\main\master\util\dbUtil\dbBaseUtil.py", line 54, in write
    ret = c.execute(sql, args)
  File "C:\Python27\lib\site-packages\MySQLdb\cursors.py", line 185, in execute
    for key, item in args.iteritems())
KeyError: 'create_username'

2018-02-23 11:03:20,405 - dbBaseHelper - 6516 - ERROR - write - write sql:
        insert into interface (name,url,create_userid,create_username,update_userid,update_username,describe,
        params,success_response,failure_response,method,format,response_type,status,remarks,projectid,groupid,gmt_create) 
        values (%(name)s,%(url)s,%(create_userid)s,%(create_username)s,%(update_userid)s,%(update_username)s,%(describe)s,
        %(params)s,%(success_response)s,%(failure_response)s,%(method)s,%(format)s,%(response_type)s,%(status)s,
        %(remarks)s,%(projectid)s,%(groupid)s,now())
         args:{u'create_username': u'jessica', u'success_response': {u'success': u'true', u'statusCode': 0}, u'name': u'interface1', u'format': 1, u'url': u'v1/interface/addInterfaceItem', u'failure_response': {u'success': u'false', u'statusCode': 0}, u'describe': u'the first interface', u'groupid': 1, u'status': 1, u'params': {u'id': 1}, u'response_type': 0, u'projectid': 1, u'remarks': u'remarks', u'create_userid': 1, u'method': 1} Exception:Traceback (most recent call last):
  File "C:\Python27\lib\site-packages\src-0.0.1-py2.7.egg\src\main\master\util\dbUtil\dbBaseHelper.py", line 58, in write
    db.write(self.sql,self.args,self.is_execute_many)
  File "C:\Python27\lib\site-packages\src-0.0.1-py2.7.egg\src\main\master\util\dbUtil\dbBaseUtil.py", line 54, in write
    ret = c.execute(sql, args)
  File "C:\Python27\lib\site-packages\MySQLdb\cursors.py", line 185, in execute
    for key, item in args.iteritems())
KeyError: 'update_userid'

2018-02-23 11:03:55,921 - dbBaseHelper - 844 - ERROR - write - write sql:
        insert into interface (name,url,create_userid,create_username,update_userid,update_username,describe,
        params,success_response,failure_response,method,format,response_type,status,remarks,projectid,groupid,gmt_create) 
        values (%(name)s,%(url)s,%(create_userid)s,%(create_username)s,%(update_userid)s,%(update_username)s,%(describe)s,
        %(params)s,%(success_response)s,%(failure_response)s,%(method)s,%(format)s,%(response_type)s,%(status)s,
        %(remarks)s,%(projectid)s,%(groupid)s,now())
         args:{u'create_username': u'jessica', u'success_response': {u'success': u'true', u'statusCode': 0}, u'name': u'interface1', u'format': 1, u'url': u'v1/interface/addInterfaceItem', u'failure_response': {u'success': u'false', u'statusCode': 0}, u'describe': u'the first interface', u'groupid': 1, u'status': 1, u'params': {u'id': 1}, u'update_username': u'', u'projectid': 1, u'remarks': u'remarks', u'response_type': 0, u'create_userid': 1, u'method': 1, u'update_userid': u''} Exception:Traceback (most recent call last):
  File "C:\Python27\lib\site-packages\src-0.0.1-py2.7.egg\src\main\master\util\dbUtil\dbBaseHelper.py", line 58, in write
    db.write(self.sql,self.args,self.is_execute_many)
  File "C:\Python27\lib\site-packages\src-0.0.1-py2.7.egg\src\main\master\util\dbUtil\dbBaseUtil.py", line 54, in write
    ret = c.execute(sql, args)
  File "C:\Python27\lib\site-packages\MySQLdb\cursors.py", line 205, in execute
    self.errorhandler(self, exc, value)
  File "C:\Python27\lib\site-packages\MySQLdb\connections.py", line 36, in defaulterrorhandler
    raise errorclass, errorvalue
ProgrammingError: (1064, "You have an error in your SQL syntax; check the manual that corresponds to your MySQL server version for the right syntax to use near 'describe,\n        params,success_response,failure_response,method,format,respons' at line 1")

2018-02-23 11:10:22,305 - dbBaseHelper - 6516 - ERROR - write - write sql:
        insert into interface (name,url,create_userid,create_username,update_userid,update_username,describe,params,success_response,failure_response,method,format,response_type,status,remarks,projectid,groupid,gmt_create) 
        values (%(name)s,%(url)s,%(create_userid)s,%(create_username)s,%(update_userid)s,%(update_username)s,%(describe)s,%(params)s,%(success_response)s,%(failure_response)s,%(method)s,%(format)s,%(response_type)s,%(status)s,%(remarks)s,%(projectid)s,%(groupid)s,now())
         args:{u'create_username': u'jessica', u'success_response': {u'success': u'true', u'statusCode': 0}, u'name': u'interface1', u'format': 1, u'url': u'v1/interface/addInterfaceItem', u'failure_response': {u'success': u'false', u'statusCode': 0}, u'describe': u'the first interface', u'groupid': 1, u'status': 1, u'params': {u'id': 1}, u'update_username': u'', u'projectid': 1, u'remarks': u'remarks', u'response_type': 0, u'create_userid': 1, u'method': 1, u'update_userid': u''} Exception:Traceback (most recent call last):
  File "C:\Python27\lib\site-packages\src-0.0.1-py2.7.egg\src\main\master\util\dbUtil\dbBaseHelper.py", line 58, in write
    db.write(self.sql,self.args,self.is_execute_many)
  File "C:\Python27\lib\site-packages\src-0.0.1-py2.7.egg\src\main\master\util\dbUtil\dbBaseUtil.py", line 54, in write
    ret = c.execute(sql, args)
  File "C:\Python27\lib\site-packages\MySQLdb\cursors.py", line 205, in execute
    self.errorhandler(self, exc, value)
  File "C:\Python27\lib\site-packages\MySQLdb\connections.py", line 36, in defaulterrorhandler
    raise errorclass, errorvalue
ProgrammingError: (1064, "You have an error in your SQL syntax; check the manual that corresponds to your MySQL server version for the right syntax to use near 'describe,params,success_response,failure_response,method,format,response_type,st' at line 1")

2018-02-23 11:11:50,296 - dbBaseHelper - 7124 - ERROR - write - write sql:
        insert into interface (name,url,create_userid,create_username,update_userid,update_username,describe,params,success_response,failure_response,method,format,response_type,status,remarks,projectid,groupid,gmt_create) values (%(name)s,%(url)s,%(create_userid)s,%(create_username)s,%(update_userid)s,%(update_username)s,%(describe)s,%(params)s,%(success_response)s,%(failure_response)s,%(method)s,%(format)s,%(response_type)s,%(status)s,%(remarks)s,%(projectid)s,%(groupid)s,now())
         args:{u'create_username': u'jessica', u'success_response': {u'success': u'true', u'statusCode': 0}, u'name': u'interface1', u'format': 1, u'url': u'v1/interface/addInterfaceItem', u'failure_response': {u'success': u'false', u'statusCode': 0}, u'describe': u'the first interface', u'groupid': 1, u'status': 1, u'params': {u'id': 1}, u'update_username': u'', u'projectid': 1, u'remarks': u'remarks', u'response_type': 0, u'create_userid': 1, u'method': 1, u'update_userid': u''} Exception:Traceback (most recent call last):
  File "C:\Python27\lib\site-packages\src-0.0.1-py2.7.egg\src\main\master\util\dbUtil\dbBaseHelper.py", line 58, in write
    db.write(self.sql,self.args,self.is_execute_many)
  File "C:\Python27\lib\site-packages\src-0.0.1-py2.7.egg\src\main\master\util\dbUtil\dbBaseUtil.py", line 54, in write
    ret = c.execute(sql, args)
  File "C:\Python27\lib\site-packages\MySQLdb\cursors.py", line 205, in execute
    self.errorhandler(self, exc, value)
  File "C:\Python27\lib\site-packages\MySQLdb\connections.py", line 36, in defaulterrorhandler
    raise errorclass, errorvalue
ProgrammingError: (1064, "You have an error in your SQL syntax; check the manual that corresponds to your MySQL server version for the right syntax to use near 'describe,params,success_response,failure_response,method,format,response_type,st' at line 1")

2018-02-23 14:32:11,801 - dbBaseHelper - 8668 - ERROR - write - write sql:
        insert into interface (name,url,create_userid,interface_describe,params,success_response,failure_response,
        method,format,response_type,status,remarks,projectid,groupid,gmt_create) 
        values (%(name)s,%(url),%(create_userid)s,%(describe)s,%(params)s,%(success_response)s,%(failure_response)s,
        %(method)s,%(format)s,%(response_type)s,%(status)s,%(remarks)s,%(projectid)s,%(groupid)s,now())
         args:{u'status': 1, u'success_response': {u'success': u'true', u'statusCode': 0}, u'name': u'interface2', u'format': 1, u'url': u'v1/interface/updateInterfaceItem', u'failure_response': {u'success': u'false', u'statusCode': 0}, u'describe': u'the first interface', u'groupid': 1, u'params': {u'id': 1}, u'response_type': 0, u'projectid': 1, u'remarks': u'remarks', u'create_userid': 1, u'method': 1} Exception:Traceback (most recent call last):
  File "C:\Python27\lib\site-packages\src-0.0.1-py2.7.egg\src\main\master\util\dbUtil\dbBaseHelper.py", line 58, in write
    db.write(self.sql,self.args,self.is_execute_many)
  File "C:\Python27\lib\site-packages\src-0.0.1-py2.7.egg\src\main\master\util\dbUtil\dbBaseUtil.py", line 54, in write
    ret = c.execute(sql, args)
  File "C:\Python27\lib\site-packages\MySQLdb\cursors.py", line 185, in execute
    for key, item in args.iteritems())
ValueError: unsupported format character ',' (0x2c) at index 229

2018-02-23 14:34:19,339 - dbBaseHelper - 9732 - ERROR - write - write sql:
        insert into interface (name,url,create_userid,interface_describe,params,success_response,failure_response,
        method,format,response_type,status,remarks,projectid,groupid,gmt_create) 
        values (%(name)s,%(url)s,%(create_userid)s,%(describe)s,%(params)s,%(success_response)s,%(failure_response)s,
        %(method)s,%(format)s,%(response_type)s,%(status)s,%(remarks)s,%(projectid)s,%(groupid)s,now())
         args:{u'status': 1, u'success_response': {u'success': u'true', u'statusCode': 0}, u'name': u'interface2', u'format': 1, u'url': u'v1/interface/updateInterfaceItem', u'failure_response': {u'success': u'false', u'statusCode': 0}, u'describe': u'the first interface', u'groupid': 1, u'params': {u'id': 1}, u'response_type': 0, u'projectid': 1, u'remarks': u'remarks', u'create_userid': 1, u'method': 1} Exception:Traceback (most recent call last):
  File "C:\Python27\lib\site-packages\src-0.0.1-py2.7.egg\src\main\master\util\dbUtil\dbBaseHelper.py", line 58, in write
    db.write(self.sql,self.args,self.is_execute_many)
  File "C:\Python27\lib\site-packages\src-0.0.1-py2.7.egg\src\main\master\util\dbUtil\dbBaseUtil.py", line 54, in write
    ret = c.execute(sql, args)
  File "C:\Python27\lib\site-packages\MySQLdb\cursors.py", line 205, in execute
    self.errorhandler(self, exc, value)
  File "C:\Python27\lib\site-packages\MySQLdb\connections.py", line 36, in defaulterrorhandler
    raise errorclass, errorvalue
ProgrammingError: (1064, 'You have an error in your SQL syntax; check the manual that corresponds to your MySQL server version for the right syntax to use near \': \'1\'},{u\'success\': "\'true\'", u\'statusCode\': \'0\'},{u\'success\': "\'false\'", u\'stat\' at line 3')

2018-02-23 14:42:19,355 - dbBaseHelper - 7388 - ERROR - write - write sql:
        insert into interface (name,url,create_userid,interface_describe,params,success_response,failure_response,
        method,format,response_type,status,remarks,projectid,groupid,gmt_create) 
        values (%(name)s,%(url)s,%(create_userid)s,%(describe)s,%(params)s,%(success_response)s,%(failure_response)s,
        %(method)s,%(format)s,%(response_type)s,%(status)s,%(remarks)s,%(projectid)s,%(groupid)s,now())
         args:{u'status': 1, u'success_response': {u'success': u'true', u'statusCode': 0}, u'name': u'interface2', u'format': 1, u'url': u'v1/interface/updateInterfaceItem', u'failure_response': {u'success': u'false', u'statusCode': 0}, u'describe': u'the first interface', u'groupid': 1, u'params': {u'id': 1}, u'response_type': 0, u'projectid': 1, u'remarks': u'remarks', u'create_userid': 1, u'method': 1} Exception:Traceback (most recent call last):
  File "C:\Python27\lib\site-packages\src-0.0.1-py2.7.egg\src\main\master\util\dbUtil\dbBaseHelper.py", line 58, in write
    db.write(self.sql,self.args,self.is_execute_many)
  File "C:\Python27\lib\site-packages\src-0.0.1-py2.7.egg\src\main\master\util\dbUtil\dbBaseUtil.py", line 54, in write
    ret = c.execute(sql, args)
  File "C:\Python27\lib\site-packages\MySQLdb\cursors.py", line 205, in execute
    self.errorhandler(self, exc, value)
  File "C:\Python27\lib\site-packages\MySQLdb\connections.py", line 36, in defaulterrorhandler
    raise errorclass, errorvalue
ProgrammingError: (1064, 'You have an error in your SQL syntax; check the manual that corresponds to your MySQL server version for the right syntax to use near \': \'1\'},{u\'success\': "\'true\'", u\'statusCode\': \'0\'},{u\'success\': "\'false\'", u\'stat\' at line 3')

2018-02-23 14:48:40,003 - dbBaseHelper - 7340 - ERROR - write - write sql:
        insert into interface (name,url,create_userid,interface_describe,params,success_response,failure_response,
        method,format,response_type,status,remarks,projectid,groupid,gmt_create) 
        values (%(name)s,%(url)s,%(create_userid)s,%(describe)s,%(params)s,%(success_response)s,%(failure_response)s,
        %(method)s,%(format)s,%(response_type)s,%(status)s,%(remarks)s,%(projectid)s,%(groupid)s,now())
         args:{u'status': 1, u'success_response': {u'success': u'true', u'statusCode': 0}, u'name': u'interface2', u'format': 1, u'url': u'v1/interface/updateInterfaceItem', u'failure_response': {u'success': u'false', u'statusCode': 0}, u'describe': u'the first interface', u'groupid': 1, u'params': {u'id': 1}, u'response_type': 0, u'projectid': 1, u'remarks': u'remarks', u'create_userid': 1, u'method': 1} Exception:Traceback (most recent call last):
  File "C:\Python27\lib\site-packages\src-0.0.1-py2.7.egg\src\main\master\util\dbUtil\dbBaseHelper.py", line 58, in write
    db.write(self.sql,self.args,self.is_execute_many)
  File "C:\Python27\lib\site-packages\src-0.0.1-py2.7.egg\src\main\master\util\dbUtil\dbBaseUtil.py", line 54, in write
    ret = c.execute(sql, args)
  File "C:\Python27\lib\site-packages\MySQLdb\cursors.py", line 205, in execute
    self.errorhandler(self, exc, value)
  File "C:\Python27\lib\site-packages\MySQLdb\connections.py", line 36, in defaulterrorhandler
    raise errorclass, errorvalue
ProgrammingError: (1064, 'You have an error in your SQL syntax; check the manual that corresponds to your MySQL server version for the right syntax to use near \': \'1\'},{u\'success\': "\'true\'", u\'statusCode\': \'0\'},{u\'success\': "\'false\'", u\'stat\' at line 3')

2018-02-23 14:56:55,849 - dbBaseHelper - 10056 - ERROR - write - write sql:
        insert into interface (name,url,create_userid,interface_describe,params,success_response,failure_response,
        method,format,response_type,status,remarks,projectid,groupid,gmt_create) 
        values (%(name)s,%(url)s,%(create_userid)s,%(describe)s,%(params)s,%(success_response)s,%(failure_response)s,
        %(method)s,%(format)s,%(response_type)s,%(status)s,%(remarks)s,%(projectid)s,%(groupid)s,now())
         args:{u'status': 1, u'success_response': {u'success': u'true', u'statusCode': 0}, u'name': u'interface2', u'format': 1, u'url': u'v1/interface/updateInterfaceItem', u'failure_response': {u'success': u'false', u'statusCode': 0}, u'describe': u'the first interface', u'groupid': 1, u'params': {u'id': 1}, u'response_type': 0, u'projectid': 1, u'remarks': u'remarks', u'create_userid': 1, u'method': 1} Exception:Traceback (most recent call last):
  File "C:\Python27\lib\site-packages\src-0.0.1-py2.7.egg\src\main\master\util\dbUtil\dbBaseHelper.py", line 58, in write
    db.write(self.sql,self.args,self.is_execute_many)
  File "C:\Python27\lib\site-packages\src-0.0.1-py2.7.egg\src\main\master\util\dbUtil\dbBaseUtil.py", line 54, in write
    ret = c.execute(sql, args)
  File "C:\Python27\lib\site-packages\MySQLdb\cursors.py", line 205, in execute
    self.errorhandler(self, exc, value)
  File "C:\Python27\lib\site-packages\MySQLdb\connections.py", line 36, in defaulterrorhandler
    raise errorclass, errorvalue
ProgrammingError: (1064, 'You have an error in your SQL syntax; check the manual that corresponds to your MySQL server version for the right syntax to use near \': \'1\'},{u\'success\': "\'true\'", u\'statusCode\': \'0\'},{u\'success\': "\'false\'", u\'stat\' at line 3')

2018-02-23 15:04:34,009 - dbBaseHelper - 9616 - ERROR - write - write sql:
        insert into interface (name,url,create_userid,interface_describe,params,success_response,failure_response,
        method,format,response_type,status,remarks,projectid,groupid,gmt_create) 
        values (%(name)s,%(url)s,%(create_userid)s,%(describe)s,%(params)s,%(success_response)s,%(failure_response)s,
        %(method)s,%(format)s,%(response_type)s,%(status)s,%(remarks)s,%(projectid)s,%(groupid)s,now())
         args:{u'status': 1, u'success_response': {u'success': u'true', u'statusCode': 0}, u'name': u'interface2', u'format': 1, u'url': u'v1/interface/updateInterfaceItem', u'failure_response': {u'success': u'false', u'statusCode': 0}, u'describe': u'the first interface', u'groupid': 1, u'params': {u'id': 1}, u'response_type': 0, u'projectid': 1, u'remarks': u'remarks', u'create_userid': 1, u'method': 1} Exception:Traceback (most recent call last):
  File "C:\Python27\lib\site-packages\src-0.0.1-py2.7.egg\src\main\master\util\dbUtil\dbBaseHelper.py", line 58, in write
    db.write(self.sql,self.args,self.is_execute_many)
  File "C:\Python27\lib\site-packages\src-0.0.1-py2.7.egg\src\main\master\util\dbUtil\dbBaseUtil.py", line 54, in write
    ret = c.execute(sql, args)
  File "C:\Python27\lib\site-packages\MySQLdb\cursors.py", line 205, in execute
    self.errorhandler(self, exc, value)
  File "C:\Python27\lib\site-packages\MySQLdb\connections.py", line 36, in defaulterrorhandler
    raise errorclass, errorvalue
ProgrammingError: (1064, 'You have an error in your SQL syntax; check the manual that corresponds to your MySQL server version for the right syntax to use near \': \'1\'},{u\'success\': "\'true\'", u\'statusCode\': \'0\'},{u\'success\': "\'false\'", u\'stat\' at line 3')

2018-02-23 15:06:59,805 - dbBaseHelper - 8768 - ERROR - write - write sql:
        insert into interface (name,url,create_userid,interface_describe,params,success_response,failure_response,
        method,format,response_type,status,remarks,projectid,groupid,gmt_create) 
        values (%(name)s,%(url)s,%(create_userid)s,%(describe)s,%(params)s,%(success_response)s,%(failure_response)s,
        %(method)s,%(format)s,%(response_type)s,%(status)s,%(remarks)s,%(projectid)s,%(groupid)s,now())
         args:{u'status': 1, u'success_response': {u'success': u'true', u'statusCode': 0}, u'name': u'interface2', u'format': 1, u'url': u'v1/interface/updateInterfaceItem', u'failure_response': {u'success': u'false', u'statusCode': 0}, u'describe': u'the first interface', u'groupid': 1, u'params': {u'id': 1}, u'response_type': 0, u'projectid': 1, u'remarks': u'remarks', u'create_userid': 1, u'method': 1} Exception:Traceback (most recent call last):
  File "C:\Python27\lib\site-packages\src-0.0.1-py2.7.egg\src\main\master\util\dbUtil\dbBaseHelper.py", line 58, in write
    db.write(self.sql,self.args,self.is_execute_many)
  File "C:\Python27\lib\site-packages\src-0.0.1-py2.7.egg\src\main\master\util\dbUtil\dbBaseUtil.py", line 54, in write
    ret = c.execute(sql, args)
  File "C:\Python27\lib\site-packages\MySQLdb\cursors.py", line 205, in execute
    self.errorhandler(self, exc, value)
  File "C:\Python27\lib\site-packages\MySQLdb\connections.py", line 36, in defaulterrorhandler
    raise errorclass, errorvalue
ProgrammingError: (1064, 'You have an error in your SQL syntax; check the manual that corresponds to your MySQL server version for the right syntax to use near \': \'1\'},{u\'success\': "\'true\'", u\'statusCode\': \'0\'},{u\'success\': "\'false\'", u\'stat\' at line 3')

2018-02-23 16:17:20,979 - dbBaseHelper - 6508 - ERROR - read - sql params [5] type is error,must be dict
2018-02-23 16:17:51,953 - dbBaseHelper - 6508 - ERROR - read - select sql:
        select * from interface where id = %(apiId)s
         args:None Exception:Traceback (most recent call last):
  File "C:\Python27\lib\site-packages\src-0.0.1-py2.7.egg\src\main\master\util\dbUtil\dbBaseHelper.py", line 30, in read
    ret = db.read(self.sql,self.args)
  File "C:\Python27\lib\site-packages\src-0.0.1-py2.7.egg\src\main\master\util\dbUtil\dbBaseUtil.py", line 39, in read
    c.execute(sql, args)
  File "C:\Python27\lib\site-packages\MySQLdb\cursors.py", line 205, in execute
    self.errorhandler(self, exc, value)
  File "C:\Python27\lib\site-packages\MySQLdb\connections.py", line 36, in defaulterrorhandler
    raise errorclass, errorvalue
ProgrammingError: (1064, "You have an error in your SQL syntax; check the manual that corresponds to your MySQL server version for the right syntax to use near '%(apiId)s' at line 1")

2018-02-23 16:18:14,301 - dbBaseHelper - 10184 - ERROR - read - sql params [5] type is error,must be dict
2018-02-23 16:22:12,042 - dbBaseHelper - 6508 - ERROR - read - sql params [5] type is error,must be dict
2018-02-23 16:22:17,832 - dbBaseHelper - 8400 - ERROR - read - sql params [6] type is error,must be dict
2018-02-23 16:34:16,642 - dbBaseHelper - 10008 - ERROR - read - sql params [6] type is error,must be dict
2018-02-23 16:35:54,676 - dbBaseHelper - 10660 - ERROR - read - sql params [6] type is error,must be dict
2018-02-23 16:38:39,151 - dbBaseHelper - 11104 - ERROR - read - sql params [6] type is error,must be dict
2018-02-23 16:41:37,305 - dbBaseHelper - 10256 - ERROR - read - sql params [6] type is error,must be dict
2018-02-23 16:41:37,305 - dbBaseHelper - 10256 - ERROR - write - write sql:
        update interface set name=%(name)s,url=%(url)s,update_userid=%(userId)s,interface_describe=%(describe)s,
        params=%(params)s,success_response=%(success_response)s,failure_response=%(failure_response)s,method=%(method)s,
        format=%(format)s,response_type=%(response_type)s,status=%(status)s,remarks=%(remarks)s) where id =%(apiId)s
         args:{u'status': 1, u'success_response': {u'success': u'true', u'statusCode': 0}, u'name': u'updateupdate', u'format': 1, u'url': u'v1/interface/updateInter', u'apiId': 6, u'describe': u'the first dfaert', u'userId': 1, u'params': {u'id': 1}, u'response_type': 0, u'remarks': u'remarks', u'failure_response': {u'success': u'false', u'statusCode': 0}, u'method': 1} Exception:Traceback (most recent call last):
  File "C:\Python27\lib\site-packages\src-0.0.1-py2.7.egg\src\main\master\util\dbUtil\dbBaseHelper.py", line 58, in write
    db.write(self.sql,self.args,self.is_execute_many)
  File "C:\Python27\lib\site-packages\src-0.0.1-py2.7.egg\src\main\master\util\dbUtil\dbBaseUtil.py", line 54, in write
    ret = c.execute(sql, args)
  File "C:\Python27\lib\site-packages\MySQLdb\cursors.py", line 205, in execute
    self.errorhandler(self, exc, value)
  File "C:\Python27\lib\site-packages\MySQLdb\connections.py", line 36, in defaulterrorhandler
    raise errorclass, errorvalue
ProgrammingError: (1064, 'You have an error in your SQL syntax; check the manual that corresponds to your MySQL server version for the right syntax to use near \': \'1\'},success_response={u\'success\': "\'true\'", u\'statusCode\': \'0\'},failure_respo\' at line 2')

2018-02-23 16:48:12,312 - dbBaseHelper - 10792 - ERROR - read - select sql:
        select * from interface where projectid=%(projectId)s and groupid=%(groupId)s 
        order by id desc limit %(offset)s,%(limit)s
         args:{'projectId': u'1', 'limit': u'10', 'groupId': u'1', 'offset': u'1'} Exception:Traceback (most recent call last):
  File "C:\Python27\lib\site-packages\src-0.0.1-py2.7.egg\src\main\master\util\dbUtil\dbBaseHelper.py", line 30, in read
    ret = db.read(self.sql,self.args)
  File "C:\Python27\lib\site-packages\src-0.0.1-py2.7.egg\src\main\master\util\dbUtil\dbBaseUtil.py", line 39, in read
    c.execute(sql, args)
  File "C:\Python27\lib\site-packages\MySQLdb\cursors.py", line 205, in execute
    self.errorhandler(self, exc, value)
  File "C:\Python27\lib\site-packages\MySQLdb\connections.py", line 36, in defaulterrorhandler
    raise errorclass, errorvalue
ProgrammingError: (1064, "You have an error in your SQL syntax; check the manual that corresponds to your MySQL server version for the right syntax to use near ''1','10'' at line 2")

2018-02-23 16:48:28,734 - dbBaseHelper - 11184 - ERROR - read - select sql:
        select * from interface where projectid=%(projectId)s and groupid=%(groupId)s 
        order by id desc limit %(offset)s,%(limit)s
         args:{'projectId': u'1', 'limit': u'3', 'groupId': u'1', 'offset': u'1'} Exception:Traceback (most recent call last):
  File "C:\Python27\lib\site-packages\src-0.0.1-py2.7.egg\src\main\master\util\dbUtil\dbBaseHelper.py", line 30, in read
    ret = db.read(self.sql,self.args)
  File "C:\Python27\lib\site-packages\src-0.0.1-py2.7.egg\src\main\master\util\dbUtil\dbBaseUtil.py", line 39, in read
    c.execute(sql, args)
  File "C:\Python27\lib\site-packages\MySQLdb\cursors.py", line 205, in execute
    self.errorhandler(self, exc, value)
  File "C:\Python27\lib\site-packages\MySQLdb\connections.py", line 36, in defaulterrorhandler
    raise errorclass, errorvalue
ProgrammingError: (1064, "You have an error in your SQL syntax; check the manual that corresponds to your MySQL server version for the right syntax to use near ''1','3'' at line 2")

2018-02-23 16:49:32,075 - dbBaseHelper - 8764 - ERROR - read - select sql:
        select * from interface where projectid=%(projectId)s and groupid=%(groupId)s 
        order by id desc limit %(offset)s,%(limit)s
         args:{'projectId': u'1', 'limit': u'5', 'groupId': u'1', 'offset': u'1'} Exception:Traceback (most recent call last):
  File "C:\Python27\lib\site-packages\src-0.0.1-py2.7.egg\src\main\master\util\dbUtil\dbBaseHelper.py", line 30, in read
    ret = db.read(self.sql,self.args)
  File "C:\Python27\lib\site-packages\src-0.0.1-py2.7.egg\src\main\master\util\dbUtil\dbBaseUtil.py", line 39, in read
    c.execute(sql, args)
  File "C:\Python27\lib\site-packages\MySQLdb\cursors.py", line 205, in execute
    self.errorhandler(self, exc, value)
  File "C:\Python27\lib\site-packages\MySQLdb\connections.py", line 36, in defaulterrorhandler
    raise errorclass, errorvalue
ProgrammingError: (1064, "You have an error in your SQL syntax; check the manual that corresponds to your MySQL server version for the right syntax to use near ''1','5'' at line 2")

2018-02-23 17:03:18,851 - dbBaseHelper - 6320 - ERROR - read - select sql:
        select * from interface where projectid=%(projectId)s and groupid=%(groupId)s 
        order by id desc limit %(offset)s,%(limit)s
         args:{'projectId': u'1', 'limit': u'5', 'groupId': u'1', 'offset': u'1'} Exception:Traceback (most recent call last):
  File "C:\Python27\lib\site-packages\src-0.0.1-py2.7.egg\src\main\master\util\dbUtil\dbBaseHelper.py", line 30, in read
    ret = db.read(self.sql,self.args)
  File "C:\Python27\lib\site-packages\src-0.0.1-py2.7.egg\src\main\master\util\dbUtil\dbBaseUtil.py", line 39, in read
    c.execute(sql, args)
  File "C:\Python27\lib\site-packages\MySQLdb\cursors.py", line 205, in execute
    self.errorhandler(self, exc, value)
  File "C:\Python27\lib\site-packages\MySQLdb\connections.py", line 36, in defaulterrorhandler
    raise errorclass, errorvalue
ProgrammingError: (1064, "You have an error in your SQL syntax; check the manual that corresponds to your MySQL server version for the right syntax to use near ''1','5'' at line 2")

2018-02-23 17:06:31,395 - dbBaseHelper - 8484 - ERROR - read - select sql:
        select * from interface where projectid=%(projectId)s and groupid=%(groupId)s 
        order by id desc limit %(offset)s,%(limit)s
         args:{'projectId': u'1', 'limit': u'5', 'groupId': u'1', 'offset': u'1'} Exception:Traceback (most recent call last):
  File "C:\Python27\lib\site-packages\src-0.0.1-py2.7.egg\src\main\master\util\dbUtil\dbBaseHelper.py", line 30, in read
    ret = db.read(self.sql,self.args)
  File "C:\Python27\lib\site-packages\src-0.0.1-py2.7.egg\src\main\master\util\dbUtil\dbBaseUtil.py", line 39, in read
    c.execute(sql, args)
  File "C:\Python27\lib\site-packages\MySQLdb\cursors.py", line 205, in execute
    self.errorhandler(self, exc, value)
  File "C:\Python27\lib\site-packages\MySQLdb\connections.py", line 36, in defaulterrorhandler
    raise errorclass, errorvalue
ProgrammingError: (1064, "You have an error in your SQL syntax; check the manual that corresponds to your MySQL server version for the right syntax to use near ''1','5'' at line 2")

2018-02-23 18:21:04,298 - dbBaseHelper - 11880 - ERROR - write - write sql:
        insert into environment (name,url,create_userid,datatemplate,dbname,dbhostname,dbport,dbusername,dbpasswd,gmt_create) 
        values (%(name)s,%(url)s,%(userId)s,%(template)s,%(dbname)s,%(dbhostname)s,%(dbport)s,%(dbusername)s,%(dbpasswd)s,now())
         args:{u'dbusername': u'xbtest', u'dbport': 3309, u'name': u'testenv', u'url': u'http://www.json.cn/', u'userId': 1, u'dbpasswd': u'gint123', u'template': {u'id': 1, u'name': u'org'}, u'dbname': u'dafwe', u'dbhostname': u'dafawere'} Exception:Traceback (most recent call last):
  File "C:\Python27\lib\site-packages\src-0.0.1-py2.7.egg\src\main\master\util\dbUtil\dbBaseHelper.py", line 58, in write
    db.write(self.sql,self.args,self.is_execute_many)
  File "C:\Python27\lib\site-packages\src-0.0.1-py2.7.egg\src\main\master\util\dbUtil\dbBaseUtil.py", line 54, in write
    ret = c.execute(sql, args)
  File "C:\Python27\lib\site-packages\MySQLdb\cursors.py", line 205, in execute
    self.errorhandler(self, exc, value)
  File "C:\Python27\lib\site-packages\MySQLdb\connections.py", line 36, in defaulterrorhandler
    raise errorclass, errorvalue
ProgrammingError: (1064, 'You have an error in your SQL syntax; check the manual that corresponds to your MySQL server version for the right syntax to use near \': \'1\', u\'name\': "\'org\'"},\'dafwe\',\'dafawere\',3309,\'xbtest\',\'gint123\',now())\' at line 2')

2018-02-23 18:21:19,808 - dbBaseHelper - 11880 - ERROR - write - write sql:
        insert into environment (name,url,create_userid,datatemplate,dbname,dbhostname,dbport,dbusername,dbpasswd,gmt_create) 
        values (%(name)s,%(url)s,%(userId)s,%(template)s,%(dbname)s,%(dbhostname)s,%(dbport)s,%(dbusername)s,%(dbpasswd)s,now())
         args:{u'dbusername': u'xbtest', u'dbport': 3309, u'name': u'testenv', u'url': u'http://www.json.cn/', u'userId': 1, u'dbpasswd': u'gint123', u'template': {u'id': 1, u'name': u'org'}, u'dbname': u'dafwe', u'dbhostname': u'dafawere'} Exception:Traceback (most recent call last):
  File "C:\Python27\lib\site-packages\src-0.0.1-py2.7.egg\src\main\master\util\dbUtil\dbBaseHelper.py", line 58, in write
    db.write(self.sql,self.args,self.is_execute_many)
  File "C:\Python27\lib\site-packages\src-0.0.1-py2.7.egg\src\main\master\util\dbUtil\dbBaseUtil.py", line 54, in write
    ret = c.execute(sql, args)
  File "C:\Python27\lib\site-packages\MySQLdb\cursors.py", line 205, in execute
    self.errorhandler(self, exc, value)
  File "C:\Python27\lib\site-packages\MySQLdb\connections.py", line 36, in defaulterrorhandler
    raise errorclass, errorvalue
ProgrammingError: (1064, 'You have an error in your SQL syntax; check the manual that corresponds to your MySQL server version for the right syntax to use near \': \'1\', u\'name\': "\'org\'"},\'dafwe\',\'dafawere\',3309,\'xbtest\',\'gint123\',now())\' at line 2')

2018-02-23 18:24:32,219 - dbBaseHelper - 11444 - ERROR - write - write sql:
        insert into environment (name,url,create_userid,datatemplate,dbname,dbhostname,dbport,dbusername,dbpasswd,gmt_create) 
        values (%(name)s,%(url)s,%(userId)s,%(template)s,%(dbname)s,%(dbhostname)s,%(dbport)s,%(dbusername)s,%(dbpasswd)s,now())
         args:{u'dbusername': u'xbtest', u'dbport': 3309, u'name': u'testenv', u'url': u'http://www.json.cn/', u'userId': 1, u'dbpasswd': u'gint123', u'template': {u'id': 1, u'name': u'org'}, u'dbname': u'dafwe', u'dbhostname': u'dafawere'} Exception:Traceback (most recent call last):
  File "C:\Python27\lib\site-packages\src-0.0.1-py2.7.egg\src\main\master\util\dbUtil\dbBaseHelper.py", line 58, in write
    db.write(self.sql,self.args,self.is_execute_many)
  File "C:\Python27\lib\site-packages\src-0.0.1-py2.7.egg\src\main\master\util\dbUtil\dbBaseUtil.py", line 54, in write
    ret = c.execute(sql, args)
  File "C:\Python27\lib\site-packages\MySQLdb\cursors.py", line 205, in execute
    self.errorhandler(self, exc, value)
  File "C:\Python27\lib\site-packages\MySQLdb\connections.py", line 36, in defaulterrorhandler
    raise errorclass, errorvalue
ProgrammingError: (1064, 'You have an error in your SQL syntax; check the manual that corresponds to your MySQL server version for the right syntax to use near \': \'1\', u\'name\': "\'org\'"},\'dafwe\',\'dafawere\',3309,\'xbtest\',\'gint123\',now())\' at line 2')

2018-02-24 10:49:06,970 - dbBaseHelper - 12700 - ERROR - write - write sql:
        insert into testcase (name,create_userid,case_describe,status,remarks,projectid,groupid,envid,gmt_create) 
        values(%(name)s,%(userId)s,%(describe)s,%(status)s,%(remarks)s,%(projectId)%,%(groupId)s,%(envId)s,now())
         args:{u'status': 0, u'envId': 2, u'name': u'testcase1', u'projectId': 1, u'describe': u'dfaerfdsfawer', u'userId': 1, u'remarks': u'dafer3412rsdf', u'groupId': 1} Exception:Traceback (most recent call last):
  File "C:\Python27\lib\site-packages\src-0.0.1-py2.7.egg\src\main\master\util\dbUtil\dbBaseHelper.py", line 58, in write
    db.write(self.sql,self.args,self.is_execute_many)
  File "C:\Python27\lib\site-packages\src-0.0.1-py2.7.egg\src\main\master\util\dbUtil\dbBaseUtil.py", line 54, in write
    ret = c.execute(sql, args)
  File "C:\Python27\lib\site-packages\MySQLdb\cursors.py", line 205, in execute
    self.errorhandler(self, exc, value)
  File "C:\Python27\lib\site-packages\MySQLdb\connections.py", line 36, in defaulterrorhandler
    raise errorclass, errorvalue
ProgrammingError: (1064, "You have an error in your SQL syntax; check the manual that corresponds to your MySQL server version for the right syntax to use near '%,1,2,now())' at line 2")

2018-02-24 10:58:53,677 - dbBaseHelper - 11976 - ERROR - read - sql params [2] type is error,must be dict
2018-02-24 11:01:21,921 - dbBaseHelper - 12696 - ERROR - read - select sql:
        select * from testcase where projectid = %(projectId)s and groupid= %(groupId)s 
        order by id desc limit %(offset)s,%(limit)s 
         args:{'projectId': u'1', 'limit': u'5', 'groupId': u'1', 'offset': u'1'} Exception:Traceback (most recent call last):
  File "C:\Python27\lib\site-packages\src-0.0.1-py2.7.egg\src\main\master\util\dbUtil\dbBaseHelper.py", line 30, in read
    ret = db.read(self.sql,self.args)
  File "C:\Python27\lib\site-packages\src-0.0.1-py2.7.egg\src\main\master\util\dbUtil\dbBaseUtil.py", line 39, in read
    c.execute(sql, args)
  File "C:\Python27\lib\site-packages\MySQLdb\cursors.py", line 205, in execute
    self.errorhandler(self, exc, value)
  File "C:\Python27\lib\site-packages\MySQLdb\connections.py", line 36, in defaulterrorhandler
    raise errorclass, errorvalue
ProgrammingError: (1064, "You have an error in your SQL syntax; check the manual that corresponds to your MySQL server version for the right syntax to use near ''1','5'' at line 2")

2018-02-26 14:44:04,808 - dbBaseHelper - 17332 - ERROR - read - sql params [3] type is error,must be dict
2018-02-26 14:44:16,045 - dbBaseHelper - 15876 - ERROR - read - sql params [3] type is error,must be dict
2018-02-26 14:44:47,336 - dbBaseHelper - 17332 - ERROR - read - sql params [2] type is error,must be dict
2018-02-26 14:47:46,232 - dbBaseHelper - 16852 - ERROR - read - sql params [2] type is error,must be dict
2018-02-26 14:49:02,903 - dbBaseHelper - 3540 - ERROR - read - sql params [2] type is error,must be dict
2018-03-02 11:47:14,168 - dbBaseHelper - 27716 - ERROR - write - write sql:
        insert into casecontent (step_name,caseid,step,interfaceid,url,method,
        format,request_params,timeout,type,sqlcontent) values (%(step_name)s,%(caseid)s,
        %(step)s,%(interfaceid),%(url)s,%(method)s,%(format)s,%(request_params)s,%(timeout)s,
        %(type)s,%(sqlcontent)s)
         args:{u'interfaceid': 1, u'format': 0, 'url': None, 'sqlcontent': None, u'caseid': 1, u'step': 1, 'params': '{"stuinfoids": [1, 2, 3], "id": 1, "package": {"id": 1}}', u'step_name': u'\u6b65\u9aa41', u'timeout': 200, u'type': 0, u'method': 0} Exception:Traceback (most recent call last):
  File "C:\Python27\lib\site-packages\src-0.0.1-py2.7.egg\src\main\master\util\dbUtil\dbBaseHelper.py", line 58, in write
    db.write(self.sql,self.args,self.is_execute_many)
  File "C:\Python27\lib\site-packages\src-0.0.1-py2.7.egg\src\main\master\util\dbUtil\dbBaseUtil.py", line 54, in write
    ret = c.execute(sql, args)
  File "C:\Python27\lib\site-packages\MySQLdb\cursors.py", line 185, in execute
    for key, item in args.iteritems())
ValueError: unsupported format character ',' (0x2c) at index 200

2018-03-02 11:52:26,608 - dbBaseHelper - 14200 - ERROR - write - write sql:
        insert into casecontent (step_name,caseid,step,interfaceid,url,method,
        format,request_params,timeout,type,sqlcontent) values (%(step_name)s,%(caseid)s,
        %(step)s,%(interfaceid),%(url)s,%(method)s,%(format)s,%(request_params)s,%(timeout)s,
        %(type)s,%(sqlcontent)s)
         args:{u'interfaceid': 1, u'format': 0, 'url': None, 'sqlcontent': None, u'caseid': 1, u'step': 1, 'params': '{"stuinfoids": [1, 2, 3], "id": 1, "package": {"id": 1}}', u'step_name': u'\u6b65\u9aa41', u'timeout': 200, u'type': 0, u'method': 0} Exception:Traceback (most recent call last):
  File "C:\Python27\lib\site-packages\src-0.0.1-py2.7.egg\src\main\master\util\dbUtil\dbBaseHelper.py", line 58, in write
    db.write(self.sql,self.args,self.is_execute_many)
  File "C:\Python27\lib\site-packages\src-0.0.1-py2.7.egg\src\main\master\util\dbUtil\dbBaseUtil.py", line 54, in write
    ret = c.execute(sql, args)
  File "C:\Python27\lib\site-packages\MySQLdb\cursors.py", line 185, in execute
    for key, item in args.iteritems())
ValueError: unsupported format character ',' (0x2c) at index 200

2018-03-02 14:09:26,825 - dbBaseHelper - 29680 - ERROR - write - write sql:
        insert into casecontent (step_name,caseid,step,interfaceid,url,method,
        format,request_params,timeout,type,sqlcontent) values (%(stepName)s,%(caseId)s,
        %(step)s,%(interfaceId)s,%(url)s,%(method)s,%(format)s,%(requestParams)s,%(timeout)s,
        %(type)s,%(sqlContent)s)
         args:{u'requestParams': {u'stuinfoids': [1, 2, 3], u'id': 1, u'package': {u'id': 1}}, u'interfaceId': 1, 'request_params': None, u'format': 0, 'url': None, u'sqlcontent': u'', u'stepName': u'\u6b65\u9aa42', u'caseId': 1, 'interfaceid': None, u'step': 1, u'timeout': 200, u'type': 0, u'method': 0} Exception:Traceback (most recent call last):
  File "C:\Python27\lib\site-packages\src-0.0.1-py2.7.egg\src\main\master\util\dbUtil\dbBaseHelper.py", line 58, in write
    db.write(self.sql,self.args,self.is_execute_many)
  File "C:\Python27\lib\site-packages\src-0.0.1-py2.7.egg\src\main\master\util\dbUtil\dbBaseUtil.py", line 54, in write
    ret = c.execute(sql, args)
  File "C:\Python27\lib\site-packages\MySQLdb\cursors.py", line 185, in execute
    for key, item in args.iteritems())
KeyError: 'sqlContent'

2018-03-02 14:09:49,711 - dbBaseHelper - 29680 - ERROR - write - write sql:
        insert into casecontent (step_name,caseid,step,interfaceid,url,method,
        format,request_params,timeout,type,sqlcontent) values (%(stepName)s,%(caseId)s,
        %(step)s,%(interfaceId)s,%(url)s,%(method)s,%(format)s,%(requestParams)s,%(timeout)s,
        %(type)s,%(sqlContent)s)
         args:{u'requestParams': {u'stuinfoids': [1, 2, 3], u'id': 1, u'package': {u'id': 1}}, u'interfaceId': 1, 'request_params': None, u'format': 0, 'url': None, u'sqlContent': u'', u'stepName': u'\u6b65\u9aa42', u'caseId': 1, 'interfaceid': None, u'step': 1, u'timeout': 200, 'sqlcontent': None, u'type': 0, u'method': 0} Exception:Traceback (most recent call last):
  File "C:\Python27\lib\site-packages\src-0.0.1-py2.7.egg\src\main\master\util\dbUtil\dbBaseHelper.py", line 58, in write
    db.write(self.sql,self.args,self.is_execute_many)
  File "C:\Python27\lib\site-packages\src-0.0.1-py2.7.egg\src\main\master\util\dbUtil\dbBaseUtil.py", line 54, in write
    ret = c.execute(sql, args)
  File "C:\Python27\lib\site-packages\MySQLdb\cursors.py", line 205, in execute
    self.errorhandler(self, exc, value)
  File "C:\Python27\lib\site-packages\MySQLdb\connections.py", line 36, in defaulterrorhandler
    raise errorclass, errorvalue
ProgrammingError: (1064, "You have an error in your SQL syntax; check the manual that corresponds to your MySQL server version for the right syntax to use near ': '(1,2,3)', u'id': '1', u'package': {u'id': '1'}},200,\n        0,'')' at line 3")

2018-03-02 14:10:35,401 - dbBaseHelper - 26192 - ERROR - write - write sql:
        insert into casecontent (step_name,caseid,step,interfaceid,url,method,
        format,request_params,timeout,type,sqlcontent) values (%(stepName)s,%(caseId)s,
        %(step)s,%(interfaceId)s,%(url)s,%(method)s,%(format)s,%(requestParams)s,%(timeout)s,
        %(type)s,%(sqlContent)s)
         args:{u'requestParams': {u'stuinfoids': 1, u'id': 1, u'package': {u'id': 1}}, u'interfaceId': 1, 'request_params': None, u'format': 0, 'url': None, u'sqlContent': u'', u'stepName': u'\u6b65\u9aa42', u'caseId': 1, 'interfaceid': None, u'step': 1, u'timeout': 200, 'sqlcontent': None, u'type': 0, u'method': 0} Exception:Traceback (most recent call last):
  File "C:\Python27\lib\site-packages\src-0.0.1-py2.7.egg\src\main\master\util\dbUtil\dbBaseHelper.py", line 58, in write
    db.write(self.sql,self.args,self.is_execute_many)
  File "C:\Python27\lib\site-packages\src-0.0.1-py2.7.egg\src\main\master\util\dbUtil\dbBaseUtil.py", line 54, in write
    ret = c.execute(sql, args)
  File "C:\Python27\lib\site-packages\MySQLdb\cursors.py", line 205, in execute
    self.errorhandler(self, exc, value)
  File "C:\Python27\lib\site-packages\MySQLdb\connections.py", line 36, in defaulterrorhandler
    raise errorclass, errorvalue
ProgrammingError: (1064, "You have an error in your SQL syntax; check the manual that corresponds to your MySQL server version for the right syntax to use near ': '1', u'id': '1', u'package': {u'id': '1'}},200,\n        0,'')' at line 3")

2018-03-02 14:12:01,403 - dbBaseHelper - 28524 - ERROR - write - write sql:
        insert into casecontent (step_name,caseid,step,interfaceid,url,method,
        format,request_params,timeout,type,sqlcontent) values (%(stepName)s,%(caseId)s,
        %(step)s,%(interfaceId)s,%(url)s,%(method)s,%(format)s,%(requestParams)s,%(timeout)s,
        %(type)s,%(sqlContent)s)
         args:{u'requestParams': {u'stuinfoids': [1, 2, 3], u'id': 1, u'package': {u'id': 1}}, u'interfaceId': 1, 'request_params': None, u'format': 0, 'url': None, u'sqlContent': u'', u'stepName': u'\u6b65\u9aa42', u'caseId': 1, 'interfaceid': None, u'step': 1, u'timeout': 200, 'sqlcontent': None, u'type': 0, u'method': 0} Exception:Traceback (most recent call last):
  File "C:\Python27\lib\site-packages\src-0.0.1-py2.7.egg\src\main\master\util\dbUtil\dbBaseHelper.py", line 58, in write
    db.write(self.sql,self.args,self.is_execute_many)
  File "C:\Python27\lib\site-packages\src-0.0.1-py2.7.egg\src\main\master\util\dbUtil\dbBaseUtil.py", line 54, in write
    ret = c.execute(sql, args)
  File "C:\Python27\lib\site-packages\MySQLdb\cursors.py", line 205, in execute
    self.errorhandler(self, exc, value)
  File "C:\Python27\lib\site-packages\MySQLdb\connections.py", line 36, in defaulterrorhandler
    raise errorclass, errorvalue
ProgrammingError: (1064, "You have an error in your SQL syntax; check the manual that corresponds to your MySQL server version for the right syntax to use near ': '(1,2,3)', u'id': '1', u'package': {u'id': '1'}},200,\n        0,'')' at line 3")

2018-03-02 14:14:14,013 - dbBaseHelper - 29628 - ERROR - write - write sql:
        insert into casecontent (step_name,caseid,step,interfaceid,url,method,
        format,request_params,timeout,type,sqlcontent) values (%(stepName)s,%(caseId)s,
        %(step)s,%(interfaceId)s,%(url)s,%(method)s,%(format)s,%(requestParams)s,%(timeout)s,
        %(type)s,%(sqlContent)s)
         args:{u'requestParams': {u'stuinfoids': [1, 2, 3], u'id': 1, u'package': {u'id': 1}}, u'interfaceId': 1, 'request_params': None, u'format': 0, 'url': None, u'sqlContent': u'', u'stepName': u'\u6b65\u9aa42', u'caseId': 1, 'interfaceid': None, u'step': 1, u'timeout': 200, 'sqlcontent': None, u'type': 0, u'method': 0} Exception:Traceback (most recent call last):
  File "C:\Python27\lib\site-packages\src-0.0.1-py2.7.egg\src\main\master\util\dbUtil\dbBaseHelper.py", line 58, in write
    db.write(self.sql,self.args,self.is_execute_many)
  File "C:\Python27\lib\site-packages\src-0.0.1-py2.7.egg\src\main\master\util\dbUtil\dbBaseUtil.py", line 54, in write
    ret = c.execute(sql, args)
  File "C:\Python27\lib\site-packages\MySQLdb\cursors.py", line 205, in execute
    self.errorhandler(self, exc, value)
  File "C:\Python27\lib\site-packages\MySQLdb\connections.py", line 36, in defaulterrorhandler
    raise errorclass, errorvalue
ProgrammingError: (1064, "You have an error in your SQL syntax; check the manual that corresponds to your MySQL server version for the right syntax to use near ': '(1,2,3)', u'id': '1', u'package': {u'id': '1'}},200,\n        0,'')' at line 3")

2018-03-02 14:38:35,388 - dbBaseHelper - 28524 - ERROR - read - sql params [1] type is error,must be dict
2018-03-02 14:39:13,799 - dbBaseHelper - 28524 - ERROR - read - sql params [4] type is error,must be dict
2018-03-02 14:48:06,798 - dbBaseHelper - 12376 - ERROR - read - sql params [1] type is error,must be dict
2018-03-02 14:48:23,348 - dbBaseHelper - 26948 - ERROR - read - sql params [1] type is error,must be dict
2018-03-02 15:04:55,365 - dbBaseHelper - 28556 - ERROR - read - sql params [1] type is error,must be dict
2018-03-05 21:09:15,835 - dbBaseHelper - 17772 - ERROR - write - write sql:
        insert into assert (casecontentid,actual,expect,assert_type,sqlcontent) 
        values (%(caseContentId)s,%(actual)s,%(expect)s,%(assertType)s,%(sqlContent)s)
         args:{u'caseContentId': 1, u'assertType': 0, u'actual': u'false', u'expect': u'false', 'sqlcontent': None} Exception:Traceback (most recent call last):
  File "C:\Python27\lib\site-packages\src-0.0.1-py2.7.egg\src\main\master\util\dbUtil\dbBaseHelper.py", line 58, in write
    db.write(self.sql,self.args,self.is_execute_many)
  File "C:\Python27\lib\site-packages\src-0.0.1-py2.7.egg\src\main\master\util\dbUtil\dbBaseUtil.py", line 54, in write
    ret = c.execute(sql, args)
  File "C:\Python27\lib\site-packages\MySQLdb\cursors.py", line 185, in execute
    for key, item in args.iteritems())
KeyError: 'sqlContent'

2018-03-05 21:10:57,506 - dbBaseHelper - 27704 - ERROR - write - write sql:
        insert into assert (casecontentid,actual,expect,assert_type,sqlcontent) 
        values (%(caseContentId)s,%(actual)s,%(expect)s,%(assertType)s,%(sqlContent)s)
         args:{u'caseContentId': 1, u'assertType': 0, u'actual': u'false', u'expect': u'false', 'sqlcontent': None} Exception:Traceback (most recent call last):
  File "C:\Python27\lib\site-packages\src-0.0.1-py2.7.egg\src\main\master\util\dbUtil\dbBaseHelper.py", line 58, in write
    db.write(self.sql,self.args,self.is_execute_many)
  File "C:\Python27\lib\site-packages\src-0.0.1-py2.7.egg\src\main\master\util\dbUtil\dbBaseUtil.py", line 54, in write
    ret = c.execute(sql, args)
  File "C:\Python27\lib\site-packages\MySQLdb\cursors.py", line 185, in execute
    for key, item in args.iteritems())
KeyError: 'sqlContent'

2018-03-05 21:13:36,875 - dbBaseHelper - 24208 - ERROR - write - write sql:
        insert into assert (casecontentid,actual,expect,assert_type,sqlcontent) 
        values (%(caseContentId)s,%(actual)s,%(expect)s,%(assertType)s,%(sqlContent)s)
         args:{u'caseContentId': 1, u'assertType': 0, u'actual': u'false', u'expect': u'false', 'sqlcontent': None} Exception:Traceback (most recent call last):
  File "C:\Python27\lib\site-packages\src-0.0.1-py2.7.egg\src\main\master\util\dbUtil\dbBaseHelper.py", line 58, in write
    db.write(self.sql,self.args,self.is_execute_many)
  File "C:\Python27\lib\site-packages\src-0.0.1-py2.7.egg\src\main\master\util\dbUtil\dbBaseUtil.py", line 54, in write
    ret = c.execute(sql, args)
  File "C:\Python27\lib\site-packages\MySQLdb\cursors.py", line 185, in execute
    for key, item in args.iteritems())
KeyError: 'sqlContent'

2018-03-05 21:22:24,244 - dbBaseHelper - 20676 - ERROR - read - sql params [1] type is error,must be dict
2018-03-05 21:24:15,717 - dbBaseHelper - 20676 - ERROR - read - sql params [2] type is error,must be dict
2018-03-06 11:45:18,075 - dbBaseHelper - 22580 - ERROR - write - write sql:
        update assert set actual=%(actual)s,expect=%(expect)s,assert_type=%(assertType)s,
        sqlcontent=%(sqlContent)s where id =%(assertId)s
         args:{u'actual': u'test9', 'sqlcontent': None, u'assertType': 1, u'assertId': 2, 'assert_type': u'0', u'expect': u'test9', 'casecontentid': 1L, 'id': 2L} Exception:Traceback (most recent call last):
  File "C:\Python27\lib\site-packages\src-0.0.1-py2.7.egg\src\main\master\util\dbUtil\dbBaseHelper.py", line 58, in write
    db.write(self.sql,self.args,self.is_execute_many)
  File "C:\Python27\lib\site-packages\src-0.0.1-py2.7.egg\src\main\master\util\dbUtil\dbBaseUtil.py", line 54, in write
    ret = c.execute(sql, args)
  File "C:\Python27\lib\site-packages\MySQLdb\cursors.py", line 185, in execute
    for key, item in args.iteritems())
KeyError: 'sqlContent'

2018-03-06 12:26:44,509 - dbBaseHelper - 14052 - ERROR - write - write sql:
        insert into assert (casecontentid,actual,expect,assert_type,sqlcontent) 
        values (%(caseContentId)s,%(actual)s,%(expect)s,%(assertType)s,%(sqlContent)s)
         args:{u'caseContentId': 3, 'expect': None, u'sqlContent': u'select * from testsuite'} Exception:Traceback (most recent call last):
  File "C:\Python27\lib\site-packages\src-0.0.1-py2.7.egg\src\main\master\util\dbUtil\dbBaseHelper.py", line 58, in write
    db.write(self.sql,self.args,self.is_execute_many)
  File "C:\Python27\lib\site-packages\src-0.0.1-py2.7.egg\src\main\master\util\dbUtil\dbBaseUtil.py", line 54, in write
    ret = c.execute(sql, args)
  File "C:\Python27\lib\site-packages\MySQLdb\cursors.py", line 185, in execute
    for key, item in args.iteritems())
KeyError: 'actual'

2018-03-06 18:55:01,351 - dbBaseHelper - 31528 - ERROR - write - write sql:
        delete from project where id = %(projectId)s
         args:{u'projectId': {u'create_username': u'', u'editting': False, u'name': u'\u548c\u8d5b\u8f66', u'_index': 5, u'gmt_modify': u'2018-03-06 18:48:28', u'edittingCell': {u'remarks': False, u'name': False}, u'gmt_create': u'2018-03-06 18:48:28', u'version': u'dasd', u'remarks': u'dasda', u'_rowKey': 6, u'create_userid': 0, u'id': 12}} Exception:Traceback (most recent call last):
  File "C:\Python27\lib\site-packages\src-0.0.1-py2.7.egg\src\main\master\util\dbUtil\dbBaseHelper.py", line 58, in write
    db.write(self.sql,self.args,self.is_execute_many)
  File "C:\Python27\lib\site-packages\src-0.0.1-py2.7.egg\src\main\master\util\dbUtil\dbBaseUtil.py", line 54, in write
    ret = c.execute(sql, args)
  File "C:\Python27\lib\site-packages\MySQLdb\cursors.py", line 205, in execute
    self.errorhandler(self, exc, value)
  File "C:\Python27\lib\site-packages\MySQLdb\connections.py", line 36, in defaulterrorhandler
    raise errorclass, errorvalue
ProgrammingError: (1064, 'You have an error in your SQL syntax; check the manual that corresponds to your MySQL server version for the right syntax to use near \': "\'\'", u\'editting\': \'0\', u\'name\': "\'\\xe5\\x92\\x8c\\xe8\\xb5\\x9b\\xe8\\xbd\\xa6\'", u\'_\' at line 1')

2018-03-08 15:10:26,490 - dbBaseHelper - 21724 - ERROR - read - select sql:
        select * from interface where id = %(interfaceId)s
         args:{'apiId': u'7'} Exception:Traceback (most recent call last):
  File "C:\Python27\lib\site-packages\src-0.0.1-py2.7.egg\src\main\master\util\dbUtil\dbBaseHelper.py", line 30, in read
    ret = db.read(self.sql,self.args)
  File "C:\Python27\lib\site-packages\src-0.0.1-py2.7.egg\src\main\master\util\dbUtil\dbBaseUtil.py", line 39, in read
    c.execute(sql, args)
  File "C:\Python27\lib\site-packages\MySQLdb\cursors.py", line 185, in execute
    for key, item in args.iteritems())
KeyError: 'interfaceId'

2018-03-08 15:15:04,398 - dbBaseHelper - 31516 - ERROR - write - sql params [6] type is error,must be dict
2018-03-09 17:58:27,707 - dbBaseHelper - 24528 - ERROR - write - write sql:
        insert into environment (name,url,create_userid,datatemplate,dbname,dbhostname,dbport,dbusername,dbpasswd,gmt_create) 
        values (%(name)s,%(url)s,%(userId)s,%(template)s,%(dbname)s,%(dbhostname)s,%(dbport)s,%(dbusername)s,%(dbpasswd)s,now())
         args:{'dbusername': None, 'dbport': None, u'name': u'test', 'url': None, 'dbpasswd': None, 'template': None, 'dbname': None, 'dbhostname': None} Exception:Traceback (most recent call last):
  File "C:\Python27\lib\site-packages\src-0.0.1-py2.7.egg\src\main\master\util\dbUtil\dbBaseHelper.py", line 58, in write
    db.write(self.sql,self.args,self.is_execute_many)
  File "C:\Python27\lib\site-packages\src-0.0.1-py2.7.egg\src\main\master\util\dbUtil\dbBaseUtil.py", line 54, in write
    ret = c.execute(sql, args)
  File "C:\Python27\lib\site-packages\MySQLdb\cursors.py", line 185, in execute
    for key, item in args.iteritems())
KeyError: 'userId'

2018-03-09 17:58:49,517 - dbBaseHelper - 24528 - ERROR - write - write sql:
        insert into environment (name,url,create_userid,datatemplate,dbname,dbhostname,dbport,dbusername,dbpasswd,gmt_create) 
        values (%(name)s,%(url)s,%(userId)s,%(template)s,%(dbname)s,%(dbhostname)s,%(dbport)s,%(dbusername)s,%(dbpasswd)s,now())
         args:{'dbusername': None, 'dbport': None, u'name': u'test', 'url': None, u'userId': 1, 'dbpasswd': None, 'template': None, 'dbname': None, 'dbhostname': None} Exception:Traceback (most recent call last):
  File "C:\Python27\lib\site-packages\src-0.0.1-py2.7.egg\src\main\master\util\dbUtil\dbBaseHelper.py", line 58, in write
    db.write(self.sql,self.args,self.is_execute_many)
  File "C:\Python27\lib\site-packages\src-0.0.1-py2.7.egg\src\main\master\util\dbUtil\dbBaseUtil.py", line 54, in write
    ret = c.execute(sql, args)
  File "C:\Python27\lib\site-packages\MySQLdb\cursors.py", line 205, in execute
    self.errorhandler(self, exc, value)
  File "C:\Python27\lib\site-packages\MySQLdb\connections.py", line 36, in defaulterrorhandler
    raise errorclass, errorvalue
OperationalError: (1048, "Column 'url' cannot be null")

