2017-12-24 21:12:42,959 - dbBaseHelper - 7800 - ERROR - write - write sql:
        insert into user (userName,phone,sex,Gmt) values (%(user_name)s,%(user_phone)s,%(user_sex)s,now())
         args:{'phone': u'1xxxxxx', 'user_name': u'jes', 'sex': 'male'} Exception:Traceback (most recent call last):
  File "C:\python27\lib\site-packages\src-0.0.1-py2.7.egg\src\main\master\util\dbUtil\dbBaseHelper.py", line 56, in write
    db.write(sql,args,is_execute_many)
  File "C:\python27\lib\site-packages\src-0.0.1-py2.7.egg\src\main\master\util\dbUtil\dbBaseUtil.py", line 54, in write
    ret = c.execute(sql, args)
  File "c:\users\jessica\appdata\local\temp\easy_install-qvdkaj\MySQL_python-1.2.5-py2.7-win32.egg.tmp\MySQLdb\cursors.py", line 185, in execute
    for key, item in args.iteritems())
KeyError: 'user_phone'

2017-12-24 21:13:48,803 - dbBaseHelper - 7128 - ERROR - write - write sql:
        insert into user (userName,phone,sex,Gmt) values (%(user_name)s,%(user_phone)s,%(user_sex)s,now())
         args:{'user_phone': u'1xxxxxx', 'user_name': u'jes', 'sex': 'male'} Exception:Traceback (most recent call last):
  File "C:\python27\lib\site-packages\src-0.0.1-py2.7.egg\src\main\master\util\dbUtil\dbBaseHelper.py", line 56, in write
    db.write(sql,args,is_execute_many)
  File "C:\python27\lib\site-packages\src-0.0.1-py2.7.egg\src\main\master\util\dbUtil\dbBaseUtil.py", line 54, in write
    ret = c.execute(sql, args)
  File "c:\users\jessica\appdata\local\temp\easy_install-qvdkaj\MySQL_python-1.2.5-py2.7-win32.egg.tmp\MySQLdb\cursors.py", line 185, in execute
    for key, item in args.iteritems())
KeyError: 'user_sex'

2017-12-31 17:26:18,226 - dbBaseHelper - 9128 - ERROR - write - func [deleteUser] exec sql Not provided
2017-12-31 17:32:52,457 - dbBaseHelper - 9128 - ERROR - write - func [deleteUser] exec sql Not provided
2017-12-31 17:35:51,237 - dbBaseHelper - 6348 - ERROR - write - func [deleteUser] exec sql Not provided
2017-12-31 17:36:49,539 - dbBaseHelper - 6348 - ERROR - write - func [deleteUser] exec sql Not provided
2017-12-31 17:40:41,964 - dbBaseHelper - 8764 - ERROR - write - func [deleteUser] exec sql Not provided
2017-12-31 17:44:26,028 - dbBaseHelper - 8328 - ERROR - write - func [deleteUser] exec sql Not provided
2017-12-31 17:49:02,953 - dbBaseHelper - 8328 - ERROR - read - func [getUserInfo] exec sql Not provided
2017-12-31 17:51:43,868 - dbBaseHelper - 9116 - ERROR - read - select sql:
        select * from user where userName= %(user_name)s
         args:None Exception:Traceback (most recent call last):
  File "C:\python27\lib\site-packages\src-0.0.1-py2.7.egg\src\main\master\util\dbUtil\dbBaseHelper.py", line 38, in read
    ret = db.read(sql,args)
  File "C:\python27\lib\site-packages\src-0.0.1-py2.7.egg\src\main\master\util\dbUtil\dbBaseUtil.py", line 39, in read
    c.execute(sql, args)
  File "c:\users\jessica\appdata\local\temp\easy_install-qvdkaj\MySQL_python-1.2.5-py2.7-win32.egg.tmp\MySQLdb\cursors.py", line 205, in execute
    self.errorhandler(self, exc, value)
  File "c:\users\jessica\appdata\local\temp\easy_install-qvdkaj\MySQL_python-1.2.5-py2.7-win32.egg.tmp\MySQLdb\connections.py", line 36, in defaulterrorhandler
    raise errorclass, errorvalue
ProgrammingError: (1064, "You have an error in your SQL syntax; check the manual that corresponds to your MySQL server version for the right syntax to use near '%(user_name)s' at line 1")

2017-12-31 17:52:05,825 - dbBaseHelper - 9116 - ERROR - write - write sql:
        delete from user where userName= %(user_name)s
         args:None Exception:Traceback (most recent call last):
  File "C:\python27\lib\site-packages\src-0.0.1-py2.7.egg\src\main\master\util\dbUtil\dbBaseHelper.py", line 72, in write
    db.write(sql,args,is_execute_many)
  File "C:\python27\lib\site-packages\src-0.0.1-py2.7.egg\src\main\master\util\dbUtil\dbBaseUtil.py", line 54, in write
    ret = c.execute(sql, args)
  File "c:\users\jessica\appdata\local\temp\easy_install-qvdkaj\MySQL_python-1.2.5-py2.7-win32.egg.tmp\MySQLdb\cursors.py", line 205, in execute
    self.errorhandler(self, exc, value)
  File "c:\users\jessica\appdata\local\temp\easy_install-qvdkaj\MySQL_python-1.2.5-py2.7-win32.egg.tmp\MySQLdb\connections.py", line 36, in defaulterrorhandler
    raise errorclass, errorvalue
ProgrammingError: (1064, "You have an error in your SQL syntax; check the manual that corresponds to your MySQL server version for the right syntax to use near '%(user_name)s' at line 1")

2017-12-31 17:56:22,082 - dbBaseHelper - 5040 - ERROR - write - write sql:
        delete from user where userName= %(user_name)s
         args:None Exception:Traceback (most recent call last):
  File "C:\python27\lib\site-packages\src-0.0.1-py2.7.egg\src\main\master\util\dbUtil\dbBaseHelper.py", line 73, in write
    db.write(sql,args,is_execute_many)
  File "C:\python27\lib\site-packages\src-0.0.1-py2.7.egg\src\main\master\util\dbUtil\dbBaseUtil.py", line 54, in write
    ret = c.execute(sql, args)
  File "c:\users\jessica\appdata\local\temp\easy_install-qvdkaj\MySQL_python-1.2.5-py2.7-win32.egg.tmp\MySQLdb\cursors.py", line 205, in execute
    self.errorhandler(self, exc, value)
  File "c:\users\jessica\appdata\local\temp\easy_install-qvdkaj\MySQL_python-1.2.5-py2.7-win32.egg.tmp\MySQLdb\connections.py", line 36, in defaulterrorhandler
    raise errorclass, errorvalue
ProgrammingError: (1064, "You have an error in your SQL syntax; check the manual that corresponds to your MySQL server version for the right syntax to use near '%(user_name)s' at line 1")

2017-12-31 17:57:03,344 - dbBaseHelper - 5040 - ERROR - read - select sql:
        select * from user where userName= %(user_name)s
         args:None Exception:Traceback (most recent call last):
  File "C:\python27\lib\site-packages\src-0.0.1-py2.7.egg\src\main\master\util\dbUtil\dbBaseHelper.py", line 38, in read
    ret = db.read(sql,args)
  File "C:\python27\lib\site-packages\src-0.0.1-py2.7.egg\src\main\master\util\dbUtil\dbBaseUtil.py", line 39, in read
    c.execute(sql, args)
  File "c:\users\jessica\appdata\local\temp\easy_install-qvdkaj\MySQL_python-1.2.5-py2.7-win32.egg.tmp\MySQLdb\cursors.py", line 205, in execute
    self.errorhandler(self, exc, value)
  File "c:\users\jessica\appdata\local\temp\easy_install-qvdkaj\MySQL_python-1.2.5-py2.7-win32.egg.tmp\MySQLdb\connections.py", line 36, in defaulterrorhandler
    raise errorclass, errorvalue
ProgrammingError: (1064, "You have an error in your SQL syntax; check the manual that corresponds to your MySQL server version for the right syntax to use near '%(user_name)s' at line 1")

2017-12-31 18:41:44,315 - dbBaseHelper - 2480 - ERROR - write - write sql:
        insert into user (userName,phone,sex,Gmt) values (%(user_name)s,%(user_phone)s,%(user_sex)s,now())
         args:{'createuserid': u'4', 'version': u'v0.1.0', 'name': u'SCP'} Exception:Traceback (most recent call last):
  File "C:\python27\lib\site-packages\src-0.0.1-py2.7.egg\src\main\master\util\dbUtil\dbBaseHelper.py", line 72, in write
    db.write(sql,self.args,self.is_execute_many)
  File "C:\python27\lib\site-packages\src-0.0.1-py2.7.egg\src\main\master\util\dbUtil\dbBaseUtil.py", line 54, in write
    ret = c.execute(sql, args)
  File "c:\users\jessica\appdata\local\temp\easy_install-qvdkaj\MySQL_python-1.2.5-py2.7-win32.egg.tmp\MySQLdb\cursors.py", line 185, in execute
    for key, item in args.iteritems())
KeyError: 'user_name'

2017-12-31 18:50:59,000 - dbBaseHelper - 6340 - ERROR - write - func [addProject] exec sql Not provided
2017-12-31 18:53:58,891 - dbBaseHelper - 6340 - ERROR - write - func [addProject] exec sql Not provided
2018-01-01 18:25:59,391 - dbBaseHelper - 8836 - ERROR - read - select sql:
        select * from project where name = %(name)s
         args:{'name': {'name': u'SCP'}} Exception:Traceback (most recent call last):
  File "C:\python27\lib\site-packages\src-0.0.1-py2.7.egg\src\main\master\util\dbUtil\dbBaseHelper.py", line 33, in read
    ret = db.read(self.sql,self.args)
  File "C:\python27\lib\site-packages\src-0.0.1-py2.7.egg\src\main\master\util\dbUtil\dbBaseUtil.py", line 39, in read
    c.execute(sql, args)
  File "c:\users\jessica\appdata\local\temp\easy_install-qvdkaj\MySQL_python-1.2.5-py2.7-win32.egg.tmp\MySQLdb\cursors.py", line 205, in execute
    self.errorhandler(self, exc, value)
  File "c:\users\jessica\appdata\local\temp\easy_install-qvdkaj\MySQL_python-1.2.5-py2.7-win32.egg.tmp\MySQLdb\connections.py", line 36, in defaulterrorhandler
    raise errorclass, errorvalue
ProgrammingError: (1064, 'You have an error in your SQL syntax; check the manual that corresponds to your MySQL server version for the right syntax to use near \'\'name\': "\'SCP\'"}\' at line 1')

2018-01-01 18:30:58,585 - dbBaseHelper - 8836 - ERROR - read - select sql:
        select * from project where name = %(name)s
         args:{'name': {'name': u'SCP'}} Exception:Traceback (most recent call last):
  File "C:\python27\lib\site-packages\src-0.0.1-py2.7.egg\src\main\master\util\dbUtil\dbBaseHelper.py", line 33, in read
    ret = db.read(self.sql,self.args)
  File "C:\python27\lib\site-packages\src-0.0.1-py2.7.egg\src\main\master\util\dbUtil\dbBaseUtil.py", line 39, in read
    c.execute(sql, args)
  File "c:\users\jessica\appdata\local\temp\easy_install-qvdkaj\MySQL_python-1.2.5-py2.7-win32.egg.tmp\MySQLdb\cursors.py", line 205, in execute
    self.errorhandler(self, exc, value)
  File "c:\users\jessica\appdata\local\temp\easy_install-qvdkaj\MySQL_python-1.2.5-py2.7-win32.egg.tmp\MySQLdb\connections.py", line 36, in defaulterrorhandler
    raise errorclass, errorvalue
ProgrammingError: (1064, 'You have an error in your SQL syntax; check the manual that corresponds to your MySQL server version for the right syntax to use near \'\'name\': "\'SCP\'"}\' at line 1')

2018-01-22 14:31:07,931 - dbBaseHelper - 7452 - ERROR - write - write sql:
        insert into user (username,passwd,remarks,gmt_create) values (%(userName)s,%(userPasswd)s,%(remarks)s,now())
         args:{u'username': u'jessica', u'passwd': u'123456', 'remarks': None} Exception:Traceback (most recent call last):
  File "C:\Python27\lib\site-packages\src-0.0.1-py2.7.egg\src\main\master\util\dbUtil\dbBaseHelper.py", line 58, in write
    db.write(self.sql,self.args,self.is_execute_many)
  File "C:\Python27\lib\site-packages\src-0.0.1-py2.7.egg\src\main\master\util\dbUtil\dbBaseUtil.py", line 54, in write
    ret = c.execute(sql, args)
  File "C:\Python27\lib\site-packages\MySQLdb\cursors.py", line 185, in execute
    for key, item in args.iteritems())
KeyError: 'userName'

2018-01-22 14:31:59,535 - dbBaseHelper - 7452 - ERROR - write - write sql:
        insert into user (username,passwd,remarks,gmt_create) values (%(userName)s,%(userPasswd)s,%(remarks)s,now())
         args:{u'userName': u'jessica', u'passwd': u'123456', 'remarks': None} Exception:Traceback (most recent call last):
  File "C:\Python27\lib\site-packages\src-0.0.1-py2.7.egg\src\main\master\util\dbUtil\dbBaseHelper.py", line 58, in write
    db.write(self.sql,self.args,self.is_execute_many)
  File "C:\Python27\lib\site-packages\src-0.0.1-py2.7.egg\src\main\master\util\dbUtil\dbBaseUtil.py", line 54, in write
    ret = c.execute(sql, args)
  File "C:\Python27\lib\site-packages\MySQLdb\cursors.py", line 185, in execute
    for key, item in args.iteritems())
KeyError: 'userPasswd'

2018-01-23 00:40:04,134 - dbBaseHelper - 1716 - ERROR - write - write sql:
        insert into project (name,create_username,create_userid,version,remarks,gmt_create) values (%(name)s,%(userName)s,%(userId)s,%(version)s,%(remarks)s,now())
         args:{'remarks': None, u'headers': {u'Content-type': u'application/json'}, 'version': None, u'data': {u'userName': u'jessica', u'remarks': u'\u5f53\u524d\u7248\u672c\u4e3av0.1.0\uff0c\u8be5\u9879\u76ee\u65b0\u589e\u62fc\u56e2\u5c0f\u7a0b\u5e8f', u'version': u'v0.1.0', u'userId': 1, u'name': u'SchoolpalShow'}, u'crossDomain': True} Exception:Traceback (most recent call last):
  File "C:\python27\lib\site-packages\src-0.0.1-py2.7.egg\src\main\master\util\dbUtil\dbBaseHelper.py", line 58, in write
    db.write(self.sql,self.args,self.is_execute_many)
  File "C:\python27\lib\site-packages\src-0.0.1-py2.7.egg\src\main\master\util\dbUtil\dbBaseUtil.py", line 54, in write
    ret = c.execute(sql, args)
  File "c:\users\jessica\appdata\local\temp\easy_install-qvdkaj\MySQL_python-1.2.5-py2.7-win32.egg.tmp\MySQLdb\cursors.py", line 185, in execute
    for key, item in args.iteritems())
KeyError: 'name'

2018-01-23 00:45:37,315 - dbBaseHelper - 4796 - ERROR - write - write sql:
        insert into project (name,create_username,create_userid,version,remarks,gmt_create) values (%(name)s,%(userName)s,%(userId)s,%(version)s,%(remarks)s,now())
         args:{'remarks': None, u'headers': {u'Content-type': u'application/json'}, 'version': None, u'data': {u'userName': u'jessica', u'remarks': u'\u5f53\u524d\u7248\u672c\u4e3av0.1.0\uff0c\u8be5\u9879\u76ee\u65b0\u589e\u62fc\u56e2\u5c0f\u7a0b\u5e8f', u'version': u'v0.1.0', u'userId': 1, u'name': u'SchoolpalShow'}, u'crossDomain': True} Exception:Traceback (most recent call last):
  File "C:\python27\lib\site-packages\src-0.0.1-py2.7.egg\src\main\master\util\dbUtil\dbBaseHelper.py", line 58, in write
    db.write(self.sql,self.args,self.is_execute_many)
  File "C:\python27\lib\site-packages\src-0.0.1-py2.7.egg\src\main\master\util\dbUtil\dbBaseUtil.py", line 54, in write
    ret = c.execute(sql, args)
  File "c:\users\jessica\appdata\local\temp\easy_install-qvdkaj\MySQL_python-1.2.5-py2.7-win32.egg.tmp\MySQLdb\cursors.py", line 185, in execute
    for key, item in args.iteritems())
KeyError: 'name'

2018-01-23 00:48:12,716 - dbBaseHelper - 4796 - ERROR - write - write sql:
        insert into project (name,create_username,create_userid,version,remarks,gmt_create) values (%(name)s,%(userName)s,%(userId)s,%(version)s,%(remarks)s,now())
         args:{'remarks': None, u'headers': {u'Content-type': u'application/json'}, 'version': None, u'params': {u'userName': u'jessica', u'remarks': u'\u5f53\u524d\u7248\u672c\u4e3av0.1.0\uff0c\u8be5\u9879\u76ee\u65b0\u589e\u62fc\u56e2\u5c0f\u7a0b\u5e8f', u'version': u'v0.1.0', u'userId': 1, u'name': u'SchoolpalShow'}, u'crossDomain': True} Exception:Traceback (most recent call last):
  File "C:\python27\lib\site-packages\src-0.0.1-py2.7.egg\src\main\master\util\dbUtil\dbBaseHelper.py", line 58, in write
    db.write(self.sql,self.args,self.is_execute_many)
  File "C:\python27\lib\site-packages\src-0.0.1-py2.7.egg\src\main\master\util\dbUtil\dbBaseUtil.py", line 54, in write
    ret = c.execute(sql, args)
  File "c:\users\jessica\appdata\local\temp\easy_install-qvdkaj\MySQL_python-1.2.5-py2.7-win32.egg.tmp\MySQLdb\cursors.py", line 185, in execute
    for key, item in args.iteritems())
KeyError: 'name'

2018-01-23 01:10:49,286 - dbBaseHelper - 6268 - ERROR - write - write sql:
        insert into project (name,create_username,create_userid,version,remarks,gmt_create) values (%(name)s,%(userName)s,%(userId)s,%(version)s,%(remarks)s,now())
         args:{u'userName': u'jessica', u'remarks': u'\u5f53\u524d\u7248\u672c\u4e3av0.1.0\uff0c\u8be5\u9879\u76ee\u65b0\u589e\u62fc\u56e2\u5c0f\u7a0b\u5e8f', u'version': u'v0.1.0', u'userId': 1, u'name': u'SchoolpalShow'} Exception:Traceback (most recent call last):
  File "C:\python27\lib\site-packages\src-0.0.1-py2.7.egg\src\main\master\util\dbUtil\dbBaseHelper.py", line 58, in write
    db.write(self.sql,self.args,self.is_execute_many)
  File "C:\python27\lib\site-packages\src-0.0.1-py2.7.egg\src\main\master\util\dbUtil\dbBaseUtil.py", line 54, in write
    ret = c.execute(sql, args)
  File "c:\users\jessica\appdata\local\temp\easy_install-qvdkaj\MySQL_python-1.2.5-py2.7-win32.egg.tmp\MySQLdb\cursors.py", line 205, in execute
    self.errorhandler(self, exc, value)
  File "c:\users\jessica\appdata\local\temp\easy_install-qvdkaj\MySQL_python-1.2.5-py2.7-win32.egg.tmp\MySQLdb\connections.py", line 36, in defaulterrorhandler
    raise errorclass, errorvalue
IntegrityError: (1062, "Duplicate entry 'SchoolpalShow' for key 'name'")

2018-01-23 18:44:40,348 - dbBaseHelper - 1372 - ERROR - write - write sql:
        insert into project (name,create_username,create_userid,version,remarks,gmt_create) values (%(name)s,%(userName)s,%(userId)s,%(version)s,%(remarks)s,now())
         args:{u'userName': u'jessica', u'remarks': u'\u5f53\u524d\u7248\u672c\u4e3av0.1.0\uff0c\u8be5\u9879\u76ee\u65b0\u589e\u62fc\u56e2\u5c0f\u7a0b\u5e8f', u'version': u'v0.1.0', u'userId': 0, u'name': u'SchoolpalShow'} Exception:Traceback (most recent call last):
  File "C:\Python27\lib\site-packages\src-0.0.1-py2.7.egg\src\main\master\util\dbUtil\dbBaseHelper.py", line 58, in write
    db.write(self.sql,self.args,self.is_execute_many)
  File "C:\Python27\lib\site-packages\src-0.0.1-py2.7.egg\src\main\master\util\dbUtil\dbBaseUtil.py", line 54, in write
    ret = c.execute(sql, args)
  File "C:\Python27\lib\site-packages\MySQLdb\cursors.py", line 205, in execute
    self.errorhandler(self, exc, value)
  File "C:\Python27\lib\site-packages\MySQLdb\connections.py", line 36, in defaulterrorhandler
    raise errorclass, errorvalue
IntegrityError: (1062, "Duplicate entry 'SchoolpalShow' for key 'name'")

2018-01-23 19:03:17,221 - dbBaseHelper - 8492 - ERROR - write - write sql:
        insert into project (name,create_username,create_userid,version,remarks,gmt_create) values (%(name)s,%(userName)s,%(userId)s,%(version)s,%(remarks)s,now())
         args:{u'userName': u'', u'remarks': u'', u'version': u'', u'userId': 0, u'name': u''} Exception:Traceback (most recent call last):
  File "C:\Python27\lib\site-packages\src-0.0.1-py2.7.egg\src\main\master\util\dbUtil\dbBaseHelper.py", line 58, in write
    db.write(self.sql,self.args,self.is_execute_many)
  File "C:\Python27\lib\site-packages\src-0.0.1-py2.7.egg\src\main\master\util\dbUtil\dbBaseUtil.py", line 54, in write
    ret = c.execute(sql, args)
  File "C:\Python27\lib\site-packages\MySQLdb\cursors.py", line 205, in execute
    self.errorhandler(self, exc, value)
  File "C:\Python27\lib\site-packages\MySQLdb\connections.py", line 36, in defaulterrorhandler
    raise errorclass, errorvalue
IntegrityError: (1062, "Duplicate entry '' for key 'name'")

2018-01-23 19:04:01,289 - dbBaseHelper - 8768 - ERROR - write - write sql:
        insert into project (name,create_username,create_userid,version,remarks,gmt_create) values (%(name)s,%(userName)s,%(userId)s,%(version)s,%(remarks)s,now())
         args:{u'userName': u'', u'remarks': u'', u'version': u'', u'userId': 0, u'name': u''} Exception:Traceback (most recent call last):
  File "C:\Python27\lib\site-packages\src-0.0.1-py2.7.egg\src\main\master\util\dbUtil\dbBaseHelper.py", line 58, in write
    db.write(self.sql,self.args,self.is_execute_many)
  File "C:\Python27\lib\site-packages\src-0.0.1-py2.7.egg\src\main\master\util\dbUtil\dbBaseUtil.py", line 54, in write
    ret = c.execute(sql, args)
  File "C:\Python27\lib\site-packages\MySQLdb\cursors.py", line 205, in execute
    self.errorhandler(self, exc, value)
  File "C:\Python27\lib\site-packages\MySQLdb\connections.py", line 36, in defaulterrorhandler
    raise errorclass, errorvalue
IntegrityError: (1062, "Duplicate entry '' for key 'name'")

2018-01-23 19:04:12,579 - dbBaseHelper - 6668 - ERROR - write - write sql:
        insert into project (name,create_username,create_userid,version,remarks,gmt_create) values (%(name)s,%(userName)s,%(userId)s,%(version)s,%(remarks)s,now())
         args:{u'userName': u'', u'remarks': u'', u'version': u'', u'userId': 0, u'name': u''} Exception:Traceback (most recent call last):
  File "C:\Python27\lib\site-packages\src-0.0.1-py2.7.egg\src\main\master\util\dbUtil\dbBaseHelper.py", line 58, in write
    db.write(self.sql,self.args,self.is_execute_many)
  File "C:\Python27\lib\site-packages\src-0.0.1-py2.7.egg\src\main\master\util\dbUtil\dbBaseUtil.py", line 54, in write
    ret = c.execute(sql, args)
  File "C:\Python27\lib\site-packages\MySQLdb\cursors.py", line 205, in execute
    self.errorhandler(self, exc, value)
  File "C:\Python27\lib\site-packages\MySQLdb\connections.py", line 36, in defaulterrorhandler
    raise errorclass, errorvalue
IntegrityError: (1062, "Duplicate entry '' for key 'name'")

2018-01-23 19:09:18,542 - dbBaseHelper - 8492 - ERROR - write - write sql:
        insert into project (name,create_username,create_userid,version,remarks,gmt_create) values (%(name)s,%(userName)s,%(userId)s,%(version)s,%(remarks)s,now())
         args:{u'userName': u'', u'remarks': u'', u'version': u'', u'userId': 0, u'name': u''} Exception:Traceback (most recent call last):
  File "C:\Python27\lib\site-packages\src-0.0.1-py2.7.egg\src\main\master\util\dbUtil\dbBaseHelper.py", line 58, in write
    db.write(self.sql,self.args,self.is_execute_many)
  File "C:\Python27\lib\site-packages\src-0.0.1-py2.7.egg\src\main\master\util\dbUtil\dbBaseUtil.py", line 54, in write
    ret = c.execute(sql, args)
  File "C:\Python27\lib\site-packages\MySQLdb\cursors.py", line 205, in execute
    self.errorhandler(self, exc, value)
  File "C:\Python27\lib\site-packages\MySQLdb\connections.py", line 36, in defaulterrorhandler
    raise errorclass, errorvalue
IntegrityError: (1062, "Duplicate entry '' for key 'name'")

2018-01-24 16:01:20,092 - dbBaseHelper - 10884 - ERROR - read - sql params [<src.main.master.service.impl.ProjectServiceImpl.ProjectService object at 0x036B47F0>] type is error,must be dict
